Workbook

Sheet Left Clicks (10 cps)
AB1: {=INDEX(I$4:I1644,MATCH(LARGE(K$4:K1644,COUNTIF(K$4:K1644,">"&1000000000)+1),K$4:K1644,1))+(1000000000-LARGE(K$4:K1644,COUNTIF(K$4:K1644,">"&1000000000)+1))/INDEX(F$4:F1644,MATCH(LARGE(K$4:K1644,COUNTIF(K$4:K1644,">"&1000000000)+1),K$4:K1644,1))} -> 7850.2479 | AC1: {=INDEX(W$4:W1644,MATCH(LARGE(Y$4:Y1644,COUNTIF(Y$4:Y1644,">"&1000000000)+1),Y$4:Y1644,1))+(1000000000-LARGE(Y$4:Y1644,COUNTIF(Y$4:Y1644,">"&1000000000)+1))/INDEX(T$4:T1644,MATCH(LARGE(Y$4:Y1644,COUNTIF(Y$4:Y1644,">"&1000000000)+1),Y$4:Y1644,1))} -> 7801.1211 | AF1: =AC1-AB1 -> -49.126806
AA2: Final Times: | AB2: =IF(AB1>3600,TRUNC(AB1/3600)&"h ","")&IF(AB1>59,IF(AND(AB1>3599,QUOTIENT(MOD(AB1,3600),60)<10),"0","")&QUOTIENT(MOD(AB1,3600),60)&"m ","")&IF(AND(AB1>=10,MOD(AB1,60)<10),"0","")&ROUNDDOWN(MOD(AB1,60),0)&"s" -> 2h 10m 50s | AC2: =IF(AC1>3600,TRUNC(AC1/3600)&"h ","")&IF(AC1>59,IF(AND(AC1>3599,QUOTIENT(MOD(AC1,3600),60)<10),"0","")&QUOTIENT(MOD(AC1,3600),60)&"m ","")&IF(AND(AC1>=10,MOD(AC1,60)<10),"0","")&ROUNDDOWN(MOD(AC1,60),0)&"s" -> 2h 10m 01s | AE2: Δt: | AF2: =IF(AF1>0,"+","")&IF(ABS(AF1)>3600,TRUNC(AF1/3600)&"h "&IF(QUOTIENT(MOD(ABS(AF1),3600),60)<10,"0","")&QUOTIENT(MOD(ABS(AF1),3600),60)&"m",TRUNC(AF1,3)) -> -49,126
B3: # | C3: Old Route | D3: Impossible | E3: Build cps | F3: Total cps | G3: Build Price | H3: Real Cost | I3: Seconds | J3: Time Passed | K3: Cookies | L3: Δ Time | M3: Δ Cookies | N3: Δ Time | O3: Δ Cookies | P3: FALSE | Q3: New Route | R3: Impossible | S3: Build cps | T3: Total cps | U3: Build Price | V3: Real Cost | W3: Seconds | X3: Time Passed | Y3: Cookies
B4: =COUNTIF(C$4:C4,C4)-COUNTIF(C$4:C4,"Sell_"&C4) -> 1 | C4: Start | D4: FALSE | E4: 0 | F4: =IF($AC$5>0,$AC$5,15) -> 10 | G4: 0 | H4: 0 | I4: 0 | J4: 0s | K4: 0 | L4: 0 | M4: 0 | N4: 0 | O4: 0 | P4: =COUNTIF(Q$4:Q4,Q4)-COUNTIF(Q$4:Q4,"Sell_"&Q4) -> 1 | Q4: Start | R4: FALSE | S4: 0 | T4: =IF($AD$5>0,$AD$5,15) -> 10 | U4: 0 | V4: 0 | W4: 0 | X4: 0s | Y4: 0
B5: =IF(COUNTA(C5:C1644)=0,"",COUNTIF(C$4:C5,C5)-COUNTIF(C$4:C5,"Sell_"&C5)) -> 1 | C5: Cursor | D5: =IFERROR(__xludf.DUMMYFUNCTION("IF(COUNTA(C5:C1644)=0,"""",IF(ISBLANK(C5),FALSE,IF(NOT(COUNTIF($AA$24:$AA$34,SUBSTITUTE(C5,""Sell_"",""""))),1,IF(REGEXMATCH(C5,""Sell_""),IF(COUNTIF(C$4:C5,SUBSTITUTE(C5,""Sell_"",""""))-COUNTIF(C$4:C4,C5)<1,1),FALSE))))"),FALSE) -> FALSE | E5: {=IF(COUNTA(C5:C1644)=0,"",SUM((COUNTIF(C$4:C5,Upgrades!$B$3:$B$13)-COUNTIF(C$4:C5,"Sell_"&Upgrades!$B$3:$B$13))*Upgrades!$D$3:$D$13))} -> 0.1 | F5: =IFERROR(__xludf.DUMMYFUNCTION("IF(COUNTA(C5:C1644)=0,"""",IF(REGEXMATCH(INDEX(FILTER(C$4:C5,C$4:C5<>""""),ROWS(FILTER(C$4:C5,C$4:C5<>""""))),""^Sell_""),INDEX(FILTER(F$4:F4,C$4:C4<>""""),ROWS(FILTER(C$4:C4,C$4:C4<>""""))),$AC$5+E5))"),10.1) -> 10.1 | G5: =IFERROR(__xludf.DUMMYFUNCTION("IF(COUNTA(C5:C1644)=0,"""",IF(C5="""",0,IF(REGEXMATCH(C5,""^Sell_""),-ROUNDDOWN(ROUNDUP(INDEX(Upgrades!$C$3:$C$13,MATCH(SUBSTITUTE(C5,""Sell_"",""""),Upgrades!$B$3:$B$13,0))*1.15^(COUNTIF(C$4:C4,SUBSTITUTE(C5,""Sell_"",""""))-COUNTIF(C$4:C4,""Sell_""&SUBS"&"TITUTE(C5,""Sell_"",""""))))/2),ROUNDUP(INDEX(Upgrades!$C$3:$C$13,MATCH(C5,Upgrades!$B$3:$B$13,0))*1.15^(COUNTIF(C$4:C4,C5)-COUNTIF(C$4:C4,""Sell_""&C5))))))"),15.0) -> 15 | H5: =IF(COUNTA(C5:C1644)=0,"",G5+IF(H4<0,H4)) -> 15 | I5: =IF(COUNTA(C5:C1644)=0,"",I4+IF(H5>0,H5,0)/F4) -> 1.5 | J5: =IF(COUNTA(C5:C1644)=0,"",IF(I5>3600,TRUNC(I5/3600)&"h ","")&IF(I5>59,IF(AND(I5>3599,QUOTIENT(MOD(I5,3600),60)<10),"0","")&QUOTIENT(MOD(I5,3600),60)&"m ","")&IF(AND(I5>=10,MOD(I5,60)<10),"0","")&ROUNDDOWN(MOD(I5,60),0)&"s") -> 1s | K5: =IF(COUNTA(C5:C1644)=0,"",K4+IF(H5>0,H5,0)) -> 15 | L5: =IFS(AND(COUNTA(C5:C1644)=0,COUNTA(Q5:Q1644)=0),"",OR(AND(K5>=1000000000,OR(Y5>=1000000000,COUNTA(Q5:Q1644)=0)),OR(Y5>=1000000000,AND(COUNTA(C5:C1644)=0,P$3=TRUE))),AF$1, AND(K5<1000000000,COUNTA(C5:C1644)>0,P$3=FALSE),TRUNC(LARGE(W$4:W1644,COUNTIF(Y$4:Y1644,">"&K5)+1)+(K5-LARGE(Y$4:Y1644,COUNTIF(Y$4:Y1644,">"&K5)+1))/LARGE(T$4:T1644,COUNTIF(Y$4:Y1644,">"&K5)+1)-I5,5),1, TRUNC(W5-LARGE(I$4:I1644,COUNTIF(K$4:K1644,">"&Y5)+1)-(Y5-LARGE(K$4:K1644,COUNTIF(K$4:K1644,">"&Y5)+1))/LARGE(F$4:F1644,COUNTIF(K$4:K1644,">"&Y5)+1),5)) -> 0 | M5: =IFERROR(__xludf.DUMMYFUNCTION("IFS(AND(COUNTA(C5:C1644)=0,COUNTA(Q5:Q1644)=0),"""",OR(AND(K5>=1000000000,OR(Y5>=1000000000,COUNTA(Q5:Q1644)=0)),OR(Y5>=1000000000,AND(COUNTA(C5:C1644)=0,P$3=TRUE))), ROUNDDOWN((AB$1-AC$1)*MAX(INDEX(T$4:T1644,MATCH(LARGE(FILTER(Y$4:Y1644,Y$4:Y1644<1000000"&"000),1),Y$4:Y1644)),INDEX(F$4:F1644,MATCH(LARGE(FILTER(K$4:K1644,K$4:K1644<1000000000),1),K$4:K1644)))),AND(K5<1000000000,COUNTA(C5:C1644)>0,P$3=FALSE), ROUNDDOWN(INDEX(Y$4:Y1644,MATCH(LARGE(FILTER(W$4:W1644,W$4:W1644<=I5),1),W$4:W1644))+(I5-LARGE(FILTER("&"W$4:W1644,W$4:W1644<=I5),1))*INDEX(T$4:T1644,MATCH(LARGE(FILTER(W$4:W1644,W$4:W1644<=I5),1),W$4:W1644))-K5),1, ROUNDDOWN(Y5-INDEX(K$4:K1644,MATCH(LARGE(FILTER(I$4:I1644,I$4:I1644<=W5),1),I$4:I1644))-(W5-LARGE(FILTER(I$4:I1644,I$4:I1644<=W5),1))*INDEX(F$4:"&"F1644,MATCH(LARGE(FILTER(I$4:I1644,I$4:I1644<=W5),1),I$4:I1644))))"),0.0) -> 0 | N5: =IF(ABS(L5)>=10000,TEXT(ROUND(L5,1),"#.#")&IF(RIGHT(TEXT(ROUND(L5,1),"#.#"))=",","0",""),L5) -> 0 | O5: =IF(ABS(M5)<1000000,M5,IF(ABS(M5)<1000000000,TEXT(ROUND(M5/1000000,1),"#.#")&IF(RIGHT(TEXT(ROUND(M5/1000000,1),"#.#"))=",","0","")&"M",TEXT(ROUND(M5/1000000000,1),"#.#")&IF(RIGHT(TEXT(ROUND(M5/1000000000,1),"#.#"))=",","0","")&"B")) -> 0 | P5: =IF(COUNTA(Q5:Q1644)=0,"",COUNTIF(Q$4:Q5,Q5)-COUNTIF(Q$4:Q5,"Sell_"&Q5)) -> 1 | Q5: Cursor | R5: =IFERROR(__xludf.DUMMYFUNCTION("IF(COUNTA(Q5:Q1644)=0,"""",IF(ISBLANK(Q5),FALSE,IF(NOT(COUNTIF($AA$24:$AA$34,SUBSTITUTE(Q5,""Sell_"",""""))),1,IF(REGEXMATCH(Q5,""Sell_""),IF(COUNTIF(Q$4:Q5,SUBSTITUTE(Q5,""Sell_"",""""))-COUNTIF(Q$4:Q4,Q5)<1,1),FALSE))))"),FALSE) -> FALSE | S5: {=IF(COUNTA(Q5:Q1644)=0,"",SUM((COUNTIF(Q$4:Q5,Upgrades!$B$3:$B$13)-COUNTIF(Q$4:Q5,"Sell_"&Upgrades!$B$3:$B$13))*Upgrades!$D$3:$D$13))} -> 0.1 | T5: =IFERROR(__xludf.DUMMYFUNCTION("IF(COUNTA(Q5:Q1644)=0,"""",IF(REGEXMATCH(INDEX(FILTER(Q$4:Q5,Q$4:Q5<>""""),ROWS(FILTER(Q$4:Q5,Q$4:Q5<>""""))),""^Sell_""),INDEX(FILTER(T$4:T4,Q$4:Q4<>""""),ROWS(FILTER(Q$4:Q4,Q$4:Q4<>""""))),$AD$5+S5))"),10.1) -> 10.1 | U5: =IFERROR(__xludf.DUMMYFUNCTION("IF(COUNTA(Q5:Q1644)=0,"""",IF(Q5="""",0,IF(REGEXMATCH(Q5,""^Sell_""),-ROUNDDOWN(ROUNDUP(INDEX(Upgrades!$C$3:$C$13,MATCH(SUBSTITUTE(Q5,""Sell_"",""""),Upgrades!$B$3:$B$13,0))*1.15^(COUNTIF(Q$4:Q4,SUBSTITUTE(Q5,""Sell_"",""""))-COUNTIF(Q$4:Q4,""Sell_""&SUBS"&"TITUTE(Q5,""Sell_"",""""))))/2),ROUNDUP(INDEX(Upgrades!$C$3:$C$13,MATCH(Q5,Upgrades!$B$3:$B$13,0))*1.15^(COUNTIF(Q$4:Q4,Q5)-COUNTIF(Q$4:Q4,""Sell_""&Q5))))))"),15.0) -> 15 | V5: =IF(COUNTA(Q5:Q1644)=0,"",U5+IF(V4<0,V4)) -> 15 | W5: =IF(COUNTA(Q5:Q1644)=0,"",W4+IF(V5>0,V5,0)/T4) -> 1.5 | X5: =IF(COUNTA(Q5:Q1644)=0,"",IF(W5>3600,TRUNC(W5/3600)&"h ","")&IF(W5>59,IF(AND(W5>3599,QUOTIENT(MOD(W5,3600),60)<10),"0","")&QUOTIENT(MOD(W5,3600),60)&"m ","")&IF(AND(W5>=10,MOD(W5,60)<10),"0","")&ROUNDDOWN(MOD(W5,60),0)&"s") -> 1s | Y5: =IF(COUNTA(Q5:Q1644)=0,"",Y4+IF(V5>0,V5,0)) -> 15 | AA5: SELECT YOUR MOUSE CPS | AC5: 10 | AD5: 10
B6: =IF(COUNTA(C6:C1645)=0,"",COUNTIF(C$4:C6,C6)-COUNTIF(C$4:C6,"Sell_"&C6)) -> 1 | C6: Farm | D6: =IFERROR(__xludf.DUMMYFUNCTION("IF(COUNTA(C6:C1644)=0,"""",IF(ISBLANK(C6),FALSE,IF(NOT(COUNTIF($AA$24:$AA$34,SUBSTITUTE(C6,""Sell_"",""""))),1,IF(REGEXMATCH(C6,""Sell_""),IF(COUNTIF(C$4:C6,SUBSTITUTE(C6,""Sell_"",""""))-COUNTIF(C$4:C5,C6)<1,1),FALSE))))"),FALSE) -> FALSE | E6: {=IF(COUNTA(C6:C1644)=0,"",SUM((COUNTIF(C$4:C6,Upgrades!$B$3:$B$13)-COUNTIF(C$4:C6,"Sell_"&Upgrades!$B$3:$B$13))*Upgrades!$D$3:$D$13))} -> 4.1 | F6: =IFERROR(__xludf.DUMMYFUNCTION("IF(COUNTA(C6:C1644)=0,"""",IF(REGEXMATCH(INDEX(FILTER(C$4:C6,C$4:C6<>""""),ROWS(FILTER(C$4:C6,C$4:C6<>""""))),""^Sell_""),INDEX(FILTER(F$4:F5,C$4:C5<>""""),ROWS(FILTER(C$4:C5,C$4:C5<>""""))),$AC$5+E6))"),14.1) -> 14.1 | G6: =IFERROR(__xludf.DUMMYFUNCTION("IF(COUNTA(C6:C1644)=0,"""",IF(C6="""",0,IF(REGEXMATCH(C6,""^Sell_""),-ROUNDDOWN(ROUNDUP(INDEX(Upgrades!$C$3:$C$13,MATCH(SUBSTITUTE(C6,""Sell_"",""""),Upgrades!$B$3:$B$13,0))*1.15^(COUNTIF(C$4:C5,SUBSTITUTE(C6,""Sell_"",""""))-COUNTIF(C$4:C5,""Sell_""&SUBS"&"TITUTE(C6,""Sell_"",""""))))/2),ROUNDUP(INDEX(Upgrades!$C$3:$C$13,MATCH(C6,Upgrades!$B$3:$B$13,0))*1.15^(COUNTIF(C$4:C5,C6)-COUNTIF(C$4:C5,""Sell_""&C6))))))"),500.0) -> 500 | H6: =IF(COUNTA(C6:C1645)=0,"",G6+IF(H5<0,H5)) -> 500 | I6: =IF(COUNTA(C6:C1645)=0,"",I5+IF(H6>0,H6,0)/F5) -> 51.00495 | J6: =IF(COUNTA(C6:C1645)=0,"",IF(I6>3600,TRUNC(I6/3600)&"h ","")&IF(I6>59,IF(AND(I6>3599,QUOTIENT(MOD(I6,3600),60)<10),"0","")&QUOTIENT(MOD(I6,3600),60)&"m ","")&IF(AND(I6>=10,MOD(I6,60)<10),"0","")&ROUNDDOWN(MOD(I6,60),0)&"s") -> 51s | K6: =IF(COUNTA(C6:C1645)=0,"",K5+IF(H6>0,H6,0)) -> 515 | L6: =IFS(AND(COUNTA(C6:C1645)=0,COUNTA(Q6:Q1645)=0),"",OR(AND(K6>=1000000000,OR(Y6>=1000000000,COUNTA(Q6:Q1645)=0)),OR(Y6>=1000000000,AND(COUNTA(C6:C1645)=0,P$3=TRUE))),AF$1, AND(K6<1000000000,COUNTA(C6:C1645)>0,P$3=FALSE),TRUNC(LARGE(W$4:W1645,COUNTIF(Y$4:Y1645,">"&K6)+1)+(K6-LARGE(Y$4:Y1645,COUNTIF(Y$4:Y1645,">"&K6)+1))/LARGE(T$4:T1645,COUNTIF(Y$4:Y1645,">"&K6)+1)-I6,5),1, TRUNC(W6-LARGE(I$4:I1645,COUNTIF(K$4:K1645,">"&Y6)+1)-(Y6-LARGE(K$4:K1645,COUNTIF(K$4:K1645,">"&Y6)+1))/LARGE(F$4:F1645,COUNTIF(K$4:K1645,">"&Y6)+1),5)) -> 0 | M6: =IFERROR(__xludf.DUMMYFUNCTION("IFS(AND(COUNTA(C6:C1644)=0,COUNTA(Q6:Q1644)=0),"""",OR(AND(K6>=1000000000,OR(Y6>=1000000000,COUNTA(Q6:Q1644)=0)),OR(Y6>=1000000000,AND(COUNTA(C6:C1644)=0,P$3=TRUE))), ROUNDDOWN((AB$1-AC$1)*MAX(INDEX(T$4:T1644,MATCH(LARGE(FILTER(Y$4:Y1644,Y$4:Y1644<1000000"&"000),1),Y$4:Y1644)),INDEX(F$4:F1644,MATCH(LARGE(FILTER(K$4:K1644,K$4:K1644<1000000000),1),K$4:K1644)))),AND(K6<1000000000,COUNTA(C6:C1644)>0,P$3=FALSE), ROUNDDOWN(INDEX(Y$4:Y1644,MATCH(LARGE(FILTER(W$4:W1644,W$4:W1644<=I6),1),W$4:W1644))+(I6-LARGE(FILTER("&"W$4:W1644,W$4:W1644<=I6),1))*INDEX(T$4:T1644,MATCH(LARGE(FILTER(W$4:W1644,W$4:W1644<=I6),1),W$4:W1644))-K6),1, ROUNDDOWN(Y6-INDEX(K$4:K1644,MATCH(LARGE(FILTER(I$4:I1644,I$4:I1644<=W6),1),I$4:I1644))-(W6-LARGE(FILTER(I$4:I1644,I$4:I1644<=W6),1))*INDEX(F$4:"&"F1644,MATCH(LARGE(FILTER(I$4:I1644,I$4:I1644<=W6),1),I$4:I1644))))"),0.0) -> 0 | N6: =IF(ABS(L6)>=10000,TEXT(ROUND(L6,1),"#.#")&IF(RIGHT(TEXT(ROUND(L6,1),"#.#"))=",","0",""),L6) -> 0 | O6: =IF(ABS(M6)<1000000,M6,IF(ABS(M6)<1000000000,TEXT(ROUND(M6/1000000,1),"#.#")&IF(RIGHT(TEXT(ROUND(M6/1000000,1),"#.#"))=",","0","")&"M",TEXT(ROUND(M6/1000000000,1),"#.#")&IF(RIGHT(TEXT(ROUND(M6/1000000000,1),"#.#"))=",","0","")&"B")) -> 0 | P6: =IF(COUNTA(Q6:Q1645)=0,"",COUNTIF(Q$4:Q6,Q6)-COUNTIF(Q$4:Q6,"Sell_"&Q6)) -> 1 | Q6: Farm | R6: =IFERROR(__xludf.DUMMYFUNCTION("IF(COUNTA(Q6:Q1644)=0,"""",IF(ISBLANK(Q6),FALSE,IF(NOT(COUNTIF($AA$24:$AA$34,SUBSTITUTE(Q6,""Sell_"",""""))),1,IF(REGEXMATCH(Q6,""Sell_""),IF(COUNTIF(Q$4:Q6,SUBSTITUTE(Q6,""Sell_"",""""))-COUNTIF(Q$4:Q5,Q6)<1,1),FALSE))))"),FALSE) -> FALSE | S6: {=IF(COUNTA(Q6:Q1644)=0,"",SUM((COUNTIF(Q$4:Q6,Upgrades!$B$3:$B$13)-COUNTIF(Q$4:Q6,"Sell_"&Upgrades!$B$3:$B$13))*Upgrades!$D$3:$D$13))} -> 4.1 | T6: =IFERROR(__xludf.DUMMYFUNCTION("IF(COUNTA(Q6:Q1644)=0,"""",IF(REGEXMATCH(INDEX(FILTER(Q$4:Q6,Q$4:Q6<>""""),ROWS(FILTER(Q$4:Q6,Q$4:Q6<>""""))),""^Sell_""),INDEX(FILTER(T$4:T5,Q$4:Q5<>""""),ROWS(FILTER(Q$4:Q5,Q$4:Q5<>""""))),$AD$5+S6))"),14.1) -> 14.1 | U6: =IFERROR(__xludf.DUMMYFUNCTION("IF(COUNTA(Q6:Q1644)=0,"""",IF(Q6="""",0,IF(REGEXMATCH(Q6,""^Sell_""),-ROUNDDOWN(ROUNDUP(INDEX(Upgrades!$C$3:$C$13,MATCH(SUBSTITUTE(Q6,""Sell_"",""""),Upgrades!$B$3:$B$13,0))*1.15^(COUNTIF(Q$4:Q5,SUBSTITUTE(Q6,""Sell_"",""""))-COUNTIF(Q$4:Q5,""Sell_""&SUBS"&"TITUTE(Q6,""Sell_"",""""))))/2),ROUNDUP(INDEX(Upgrades!$C$3:$C$13,MATCH(Q6,Upgrades!$B$3:$B$13,0))*1.15^(COUNTIF(Q$4:Q5,Q6)-COUNTIF(Q$4:Q5,""Sell_""&Q6))))))"),500.0) -> 500 | V6: =IF(COUNTA(Q6:Q1645)=0,"",U6+IF(V5<0,V5)) -> 500 | W6: =IF(COUNTA(Q6:Q1645)=0,"",W5+IF(V6>0,V6,0)/T5) -> 51.00495 | X6: =IF(COUNTA(Q6:Q1645)=0,"",IF(W6>3600,TRUNC(W6/3600)&"h ","")&IF(W6>59,IF(AND(W6>3599,QUOTIENT(MOD(W6,3600),60)<10),"0","")&QUOTIENT(MOD(W6,3600),60)&"m ","")&IF(AND(W6>=10,MOD(W6,60)<10),"0","")&ROUNDDOWN(MOD(W6,60),0)&"s") -> 51s | Y6: =IF(COUNTA(Q6:Q1645)=0,"",Y5+IF(V6>0,V6,0)) -> 515
B7: =IF(COUNTA(C7:C1646)=0,"",COUNTIF(C$4:C7,C7)-COUNTIF(C$4:C7,"Sell_"&C7)) -> 2 | C7: Cursor | D7: =IFERROR(__xludf.DUMMYFUNCTION("IF(COUNTA(C7:C1644)=0,"""",IF(ISBLANK(C7),FALSE,IF(NOT(COUNTIF($AA$24:$AA$34,SUBSTITUTE(C7,""Sell_"",""""))),1,IF(REGEXMATCH(C7,""Sell_""),IF(COUNTIF(C$4:C7,SUBSTITUTE(C7,""Sell_"",""""))-COUNTIF(C$4:C6,C7)<1,1),FALSE))))"),FALSE) -> FALSE | E7: {=IF(COUNTA(C7:C1644)=0,"",SUM((COUNTIF(C$4:C7,Upgrades!$B$3:$B$13)-COUNTIF(C$4:C7,"Sell_"&Upgrades!$B$3:$B$13))*Upgrades!$D$3:$D$13))} -> 4.2 | F7: =IFERROR(__xludf.DUMMYFUNCTION("IF(COUNTA(C7:C1644)=0,"""",IF(REGEXMATCH(INDEX(FILTER(C$4:C7,C$4:C7<>""""),ROWS(FILTER(C$4:C7,C$4:C7<>""""))),""^Sell_""),INDEX(FILTER(F$4:F6,C$4:C6<>""""),ROWS(FILTER(C$4:C6,C$4:C6<>""""))),$AC$5+E7))"),14.2) -> 14.2 | G7: =IFERROR(__xludf.DUMMYFUNCTION("IF(COUNTA(C7:C1644)=0,"""",IF(C7="""",0,IF(REGEXMATCH(C7,""^Sell_""),-ROUNDDOWN(ROUNDUP(INDEX(Upgrades!$C$3:$C$13,MATCH(SUBSTITUTE(C7,""Sell_"",""""),Upgrades!$B$3:$B$13,0))*1.15^(COUNTIF(C$4:C6,SUBSTITUTE(C7,""Sell_"",""""))-COUNTIF(C$4:C6,""Sell_""&SUBS"&"TITUTE(C7,""Sell_"",""""))))/2),ROUNDUP(INDEX(Upgrades!$C$3:$C$13,MATCH(C7,Upgrades!$B$3:$B$13,0))*1.15^(COUNTIF(C$4:C6,C7)-COUNTIF(C$4:C6,""Sell_""&C7))))))"),18.0) -> 18 | H7: =IF(COUNTA(C7:C1646)=0,"",G7+IF(H6<0,H6)) -> 18 | I7: =IF(COUNTA(C7:C1646)=0,"",I6+IF(H7>0,H7,0)/F6) -> 52.281546 | J7: =IF(COUNTA(C7:C1646)=0,"",IF(I7>3600,TRUNC(I7/3600)&"h ","")&IF(I7>59,IF(AND(I7>3599,QUOTIENT(MOD(I7,3600),60)<10),"0","")&QUOTIENT(MOD(I7,3600),60)&"m ","")&IF(AND(I7>=10,MOD(I7,60)<10),"0","")&ROUNDDOWN(MOD(I7,60),0)&"s") -> 52s | K7: =IF(COUNTA(C7:C1646)=0,"",K6+IF(H7>0,H7,0)) -> 533 | L7: =IFS(AND(COUNTA(C7:C1646)=0,COUNTA(Q7:Q1646)=0),"",OR(AND(K7>=1000000000,OR(Y7>=1000000000,COUNTA(Q7:Q1646)=0)),OR(Y7>=1000000000,AND(COUNTA(C7:C1646)=0,P$3=TRUE))),AF$1, AND(K7<1000000000,COUNTA(C7:C1646)>0,P$3=FALSE),TRUNC(LARGE(W$4:W1646,COUNTIF(Y$4:Y1646,">"&K7)+1)+(K7-LARGE(Y$4:Y1646,COUNTIF(Y$4:Y1646,">"&K7)+1))/LARGE(T$4:T1646,COUNTIF(Y$4:Y1646,">"&K7)+1)-I7,5),1, TRUNC(W7-LARGE(I$4:I1646,COUNTIF(K$4:K1646,">"&Y7)+1)-(Y7-LARGE(K$4:K1646,COUNTIF(K$4:K1646,">"&Y7)+1))/LARGE(F$4:F1646,COUNTIF(K$4:K1646,">"&Y7)+1),5)) -> 0 | M7: =IFERROR(__xludf.DUMMYFUNCTION("IFS(AND(COUNTA(C7:C1644)=0,COUNTA(Q7:Q1644)=0),"""",OR(AND(K7>=1000000000,OR(Y7>=1000000000,COUNTA(Q7:Q1644)=0)),OR(Y7>=1000000000,AND(COUNTA(C7:C1644)=0,P$3=TRUE))), ROUNDDOWN((AB$1-AC$1)*MAX(INDEX(T$4:T1644,MATCH(LARGE(FILTER(Y$4:Y1644,Y$4:Y1644<1000000"&"000),1),Y$4:Y1644)),INDEX(F$4:F1644,MATCH(LARGE(FILTER(K$4:K1644,K$4:K1644<1000000000),1),K$4:K1644)))),AND(K7<1000000000,COUNTA(C7:C1644)>0,P$3=FALSE), ROUNDDOWN(INDEX(Y$4:Y1644,MATCH(LARGE(FILTER(W$4:W1644,W$4:W1644<=I7),1),W$4:W1644))+(I7-LARGE(FILTER("&"W$4:W1644,W$4:W1644<=I7),1))*INDEX(T$4:T1644,MATCH(LARGE(FILTER(W$4:W1644,W$4:W1644<=I7),1),W$4:W1644))-K7),1, ROUNDDOWN(Y7-INDEX(K$4:K1644,MATCH(LARGE(FILTER(I$4:I1644,I$4:I1644<=W7),1),I$4:I1644))-(W7-LARGE(FILTER(I$4:I1644,I$4:I1644<=W7),1))*INDEX(F$4:"&"F1644,MATCH(LARGE(FILTER(I$4:I1644,I$4:I1644<=W7),1),I$4:I1644))))"),0.0) -> 0 | N7: =IF(ABS(L7)>=10000,TEXT(ROUND(L7,1),"#.#")&IF(RIGHT(TEXT(ROUND(L7,1),"#.#"))=",","0",""),L7) -> 0 | O7: =IF(ABS(M7)<1000000,M7,IF(ABS(M7)<1000000000,TEXT(ROUND(M7/1000000,1),"#.#")&IF(RIGHT(TEXT(ROUND(M7/1000000,1),"#.#"))=",","0","")&"M",TEXT(ROUND(M7/1000000000,1),"#.#")&IF(RIGHT(TEXT(ROUND(M7/1000000000,1),"#.#"))=",","0","")&"B")) -> 0 | P7: =IF(COUNTA(Q7:Q1646)=0,"",COUNTIF(Q$4:Q7,Q7)-COUNTIF(Q$4:Q7,"Sell_"&Q7)) -> 2 | Q7: Cursor | R7: =IFERROR(__xludf.DUMMYFUNCTION("IF(COUNTA(Q7:Q1644)=0,"""",IF(ISBLANK(Q7),FALSE,IF(NOT(COUNTIF($AA$24:$AA$34,SUBSTITUTE(Q7,""Sell_"",""""))),1,IF(REGEXMATCH(Q7,""Sell_""),IF(COUNTIF(Q$4:Q7,SUBSTITUTE(Q7,""Sell_"",""""))-COUNTIF(Q$4:Q6,Q7)<1,1),FALSE))))"),FALSE) -> FALSE | S7: {=IF(COUNTA(Q7:Q1644)=0,"",SUM((COUNTIF(Q$4:Q7,Upgrades!$B$3:$B$13)-COUNTIF(Q$4:Q7,"Sell_"&Upgrades!$B$3:$B$13))*Upgrades!$D$3:$D$13))} -> 4.2 | T7: =IFERROR(__xludf.DUMMYFUNCTION("IF(COUNTA(Q7:Q1644)=0,"""",IF(REGEXMATCH(INDEX(FILTER(Q$4:Q7,Q$4:Q7<>""""),ROWS(FILTER(Q$4:Q7,Q$4:Q7<>""""))),""^Sell_""),INDEX(FILTER(T$4:T6,Q$4:Q6<>""""),ROWS(FILTER(Q$4:Q6,Q$4:Q6<>""""))),$AD$5+S7))"),14.2) -> 14.2 | U7: =IFERROR(__xludf.DUMMYFUNCTION("IF(COUNTA(Q7:Q1644)=0,"""",IF(Q7="""",0,IF(REGEXMATCH(Q7,""^Sell_""),-ROUNDDOWN(ROUNDUP(INDEX(Upgrades!$C$3:$C$13,MATCH(SUBSTITUTE(Q7,""Sell_"",""""),Upgrades!$B$3:$B$13,0))*1.15^(COUNTIF(Q$4:Q6,SUBSTITUTE(Q7,""Sell_"",""""))-COUNTIF(Q$4:Q6,""Sell_""&SUBS"&"TITUTE(Q7,""Sell_"",""""))))/2),ROUNDUP(INDEX(Upgrades!$C$3:$C$13,MATCH(Q7,Upgrades!$B$3:$B$13,0))*1.15^(COUNTIF(Q$4:Q6,Q7)-COUNTIF(Q$4:Q6,""Sell_""&Q7))))))"),18.0) -> 18 | V7: =IF(COUNTA(Q7:Q1646)=0,"",U7+IF(V6<0,V6)) -> 18 | W7: =IF(COUNTA(Q7:Q1646)=0,"",W6+IF(V7>0,V7,0)/T6) -> 52.281546 | X7: =IF(COUNTA(Q7:Q1646)=0,"",IF(W7>3600,TRUNC(W7/3600)&"h ","")&IF(W7>59,IF(AND(W7>3599,QUOTIENT(MOD(W7,3600),60)<10),"0","")&QUOTIENT(MOD(W7,3600),60)&"m ","")&IF(AND(W7>=10,MOD(W7,60)<10),"0","")&ROUNDDOWN(MOD(W7,60),0)&"s") -> 52s | Y7: =IF(COUNTA(Q7:Q1646)=0,"",Y6+IF(V7>0,V7,0)) -> 533 | AA7: Did you find a better route? | AC7: =IF(AF1<0,"YES","NO") -> YES
B8: =IF(COUNTA(C8:C1647)=0,"",COUNTIF(C$4:C8,C8)-COUNTIF(C$4:C8,"Sell_"&C8)) -> 2 | C8: Farm | D8: =IFERROR(__xludf.DUMMYFUNCTION("IF(COUNTA(C8:C1644)=0,"""",IF(ISBLANK(C8),FALSE,IF(NOT(COUNTIF($AA$24:$AA$34,SUBSTITUTE(C8,""Sell_"",""""))),1,IF(REGEXMATCH(C8,""Sell_""),IF(COUNTIF(C$4:C8,SUBSTITUTE(C8,""Sell_"",""""))-COUNTIF(C$4:C7,C8)<1,1),FALSE))))"),FALSE) -> FALSE | E8: {=IF(COUNTA(C8:C1644)=0,"",SUM((COUNTIF(C$4:C8,Upgrades!$B$3:$B$13)-COUNTIF(C$4:C8,"Sell_"&Upgrades!$B$3:$B$13))*Upgrades!$D$3:$D$13))} -> 8.2 | F8: =IFERROR(__xludf.DUMMYFUNCTION("IF(COUNTA(C8:C1644)=0,"""",IF(REGEXMATCH(INDEX(FILTER(C$4:C8,C$4:C8<>""""),ROWS(FILTER(C$4:C8,C$4:C8<>""""))),""^Sell_""),INDEX(FILTER(F$4:F7,C$4:C7<>""""),ROWS(FILTER(C$4:C7,C$4:C7<>""""))),$AC$5+E8))"),18.2) -> 18.2 | G8: =IFERROR(__xludf.DUMMYFUNCTION("IF(COUNTA(C8:C1644)=0,"""",IF(C8="""",0,IF(REGEXMATCH(C8,""^Sell_""),-ROUNDDOWN(ROUNDUP(INDEX(Upgrades!$C$3:$C$13,MATCH(SUBSTITUTE(C8,""Sell_"",""""),Upgrades!$B$3:$B$13,0))*1.15^(COUNTIF(C$4:C7,SUBSTITUTE(C8,""Sell_"",""""))-COUNTIF(C$4:C7,""Sell_""&SUBS"&"TITUTE(C8,""Sell_"",""""))))/2),ROUNDUP(INDEX(Upgrades!$C$3:$C$13,MATCH(C8,Upgrades!$B$3:$B$13,0))*1.15^(COUNTIF(C$4:C7,C8)-COUNTIF(C$4:C7,""Sell_""&C8))))))"),575.0) -> 575 | H8: =IF(COUNTA(C8:C1647)=0,"",G8+IF(H7<0,H7)) -> 575 | I8: =IF(COUNTA(C8:C1647)=0,"",I7+IF(H8>0,H8,0)/F7) -> 92.774504 | J8: =IF(COUNTA(C8:C1647)=0,"",IF(I8>3600,TRUNC(I8/3600)&"h ","")&IF(I8>59,IF(AND(I8>3599,QUOTIENT(MOD(I8,3600),60)<10),"0","")&QUOTIENT(MOD(I8,3600),60)&"m ","")&IF(AND(I8>=10,MOD(I8,60)<10),"0","")&ROUNDDOWN(MOD(I8,60),0)&"s") -> 1m 32s | K8: =IF(COUNTA(C8:C1647)=0,"",K7+IF(H8>0,H8,0)) -> 1108 | L8: =IFS(AND(COUNTA(C8:C1647)=0,COUNTA(Q8:Q1647)=0),"",OR(AND(K8>=1000000000,OR(Y8>=1000000000,COUNTA(Q8:Q1647)=0)),OR(Y8>=1000000000,AND(COUNTA(C8:C1647)=0,P$3=TRUE))),AF$1, AND(K8<1000000000,COUNTA(C8:C1647)>0,P$3=FALSE),TRUNC(LARGE(W$4:W1647,COUNTIF(Y$4:Y1647,">"&K8)+1)+(K8-LARGE(Y$4:Y1647,COUNTIF(Y$4:Y1647,">"&K8)+1))/LARGE(T$4:T1647,COUNTIF(Y$4:Y1647,">"&K8)+1)-I8,5),1, TRUNC(W8-LARGE(I$4:I1647,COUNTIF(K$4:K1647,">"&Y8)+1)-(Y8-LARGE(K$4:K1647,COUNTIF(K$4:K1647,">"&Y8)+1))/LARGE(F$4:F1647,COUNTIF(K$4:K1647,">"&Y8)+1),5)) -> 0 | M8: =IFERROR(__xludf.DUMMYFUNCTION("IFS(AND(COUNTA(C8:C1644)=0,COUNTA(Q8:Q1644)=0),"""",OR(AND(K8>=1000000000,OR(Y8>=1000000000,COUNTA(Q8:Q1644)=0)),OR(Y8>=1000000000,AND(COUNTA(C8:C1644)=0,P$3=TRUE))), ROUNDDOWN((AB$1-AC$1)*MAX(INDEX(T$4:T1644,MATCH(LARGE(FILTER(Y$4:Y1644,Y$4:Y1644<1000000"&"000),1),Y$4:Y1644)),INDEX(F$4:F1644,MATCH(LARGE(FILTER(K$4:K1644,K$4:K1644<1000000000),1),K$4:K1644)))),AND(K8<1000000000,COUNTA(C8:C1644)>0,P$3=FALSE), ROUNDDOWN(INDEX(Y$4:Y1644,MATCH(LARGE(FILTER(W$4:W1644,W$4:W1644<=I8),1),W$4:W1644))+(I8-LARGE(FILTER("&"W$4:W1644,W$4:W1644<=I8),1))*INDEX(T$4:T1644,MATCH(LARGE(FILTER(W$4:W1644,W$4:W1644<=I8),1),W$4:W1644))-K8),1, ROUNDDOWN(Y8-INDEX(K$4:K1644,MATCH(LARGE(FILTER(I$4:I1644,I$4:I1644<=W8),1),I$4:I1644))-(W8-LARGE(FILTER(I$4:I1644,I$4:I1644<=W8),1))*INDEX(F$4:"&"F1644,MATCH(LARGE(FILTER(I$4:I1644,I$4:I1644<=W8),1),I$4:I1644))))"),0.0) -> 0 | N8: =IF(ABS(L8)>=10000,TEXT(ROUND(L8,1),"#.#")&IF(RIGHT(TEXT(ROUND(L8,1),"#.#"))=",","0",""),L8) -> 0 | O8: =IF(ABS(M8)<1000000,M8,IF(ABS(M8)<1000000000,TEXT(ROUND(M8/1000000,1),"#.#")&IF(RIGHT(TEXT(ROUND(M8/1000000,1),"#.#"))=",","0","")&"M",TEXT(ROUND(M8/1000000000,1),"#.#")&IF(RIGHT(TEXT(ROUND(M8/1000000000,1),"#.#"))=",","0","")&"B")) -> 0 | P8: =IF(COUNTA(Q8:Q1647)=0,"",COUNTIF(Q$4:Q8,Q8)-COUNTIF(Q$4:Q8,"Sell_"&Q8)) -> 2 | Q8: Farm | R8: =IFERROR(__xludf.DUMMYFUNCTION("IF(COUNTA(Q8:Q1644)=0,"""",IF(ISBLANK(Q8),FALSE,IF(NOT(COUNTIF($AA$24:$AA$34,SUBSTITUTE(Q8,""Sell_"",""""))),1,IF(REGEXMATCH(Q8,""Sell_""),IF(COUNTIF(Q$4:Q8,SUBSTITUTE(Q8,""Sell_"",""""))-COUNTIF(Q$4:Q7,Q8)<1,1),FALSE))))"),FALSE) -> FALSE | S8: {=IF(COUNTA(Q8:Q1644)=0,"",SUM((COUNTIF(Q$4:Q8,Upgrades!$B$3:$B$13)-COUNTIF(Q$4:Q8,"Sell_"&Upgrades!$B$3:$B$13))*Upgrades!$D$3:$D$13))} -> 8.2 | T8: =IFERROR(__xludf.DUMMYFUNCTION("IF(COUNTA(Q8:Q1644)=0,"""",IF(REGEXMATCH(INDEX(FILTER(Q$4:Q8,Q$4:Q8<>""""),ROWS(FILTER(Q$4:Q8,Q$4:Q8<>""""))),""^Sell_""),INDEX(FILTER(T$4:T7,Q$4:Q7<>""""),ROWS(FILTER(Q$4:Q7,Q$4:Q7<>""""))),$AD$5+S8))"),18.2) -> 18.2 | U8: =IFERROR(__xludf.DUMMYFUNCTION("IF(COUNTA(Q8:Q1644)=0,"""",IF(Q8="""",0,IF(REGEXMATCH(Q8,""^Sell_""),-ROUNDDOWN(ROUNDUP(INDEX(Upgrades!$C$3:$C$13,MATCH(SUBSTITUTE(Q8,""Sell_"",""""),Upgrades!$B$3:$B$13,0))*1.15^(COUNTIF(Q$4:Q7,SUBSTITUTE(Q8,""Sell_"",""""))-COUNTIF(Q$4:Q7,""Sell_""&SUBS"&"TITUTE(Q8,""Sell_"",""""))))/2),ROUNDUP(INDEX(Upgrades!$C$3:$C$13,MATCH(Q8,Upgrades!$B$3:$B$13,0))*1.15^(COUNTIF(Q$4:Q7,Q8)-COUNTIF(Q$4:Q7,""Sell_""&Q8))))))"),575.0) -> 575 | V8: =IF(COUNTA(Q8:Q1647)=0,"",U8+IF(V7<0,V7)) -> 575 | W8: =IF(COUNTA(Q8:Q1647)=0,"",W7+IF(V8>0,V8,0)/T7) -> 92.774504 | X8: =IF(COUNTA(Q8:Q1647)=0,"",IF(W8>3600,TRUNC(W8/3600)&"h ","")&IF(W8>59,IF(AND(W8>3599,QUOTIENT(MOD(W8,3600),60)<10),"0","")&QUOTIENT(MOD(W8,3600),60)&"m ","")&IF(AND(W8>=10,MOD(W8,60)<10),"0","")&ROUNDDOWN(MOD(W8,60),0)&"s") -> 1m 32s | Y8: =IF(COUNTA(Q8:Q1647)=0,"",Y7+IF(V8>0,V8,0)) -> 1108
B9: =IF(COUNTA(C9:C1648)=0,"",COUNTIF(C$4:C9,C9)-COUNTIF(C$4:C9,"Sell_"&C9)) -> 3 | C9: Cursor | D9: =IFERROR(__xludf.DUMMYFUNCTION("IF(COUNTA(C9:C1644)=0,"""",IF(ISBLANK(C9),FALSE,IF(NOT(COUNTIF($AA$24:$AA$34,SUBSTITUTE(C9,""Sell_"",""""))),1,IF(REGEXMATCH(C9,""Sell_""),IF(COUNTIF(C$4:C9,SUBSTITUTE(C9,""Sell_"",""""))-COUNTIF(C$4:C8,C9)<1,1),FALSE))))"),FALSE) -> FALSE | E9: {=IF(COUNTA(C9:C1644)=0,"",SUM((COUNTIF(C$4:C9,Upgrades!$B$3:$B$13)-COUNTIF(C$4:C9,"Sell_"&Upgrades!$B$3:$B$13))*Upgrades!$D$3:$D$13))} -> 8.3 | F9: =IFERROR(__xludf.DUMMYFUNCTION("IF(COUNTA(C9:C1644)=0,"""",IF(REGEXMATCH(INDEX(FILTER(C$4:C9,C$4:C9<>""""),ROWS(FILTER(C$4:C9,C$4:C9<>""""))),""^Sell_""),INDEX(FILTER(F$4:F8,C$4:C8<>""""),ROWS(FILTER(C$4:C8,C$4:C8<>""""))),$AC$5+E9))"),18.3) -> 18.3 | G9: =IFERROR(__xludf.DUMMYFUNCTION("IF(COUNTA(C9:C1644)=0,"""",IF(C9="""",0,IF(REGEXMATCH(C9,""^Sell_""),-ROUNDDOWN(ROUNDUP(INDEX(Upgrades!$C$3:$C$13,MATCH(SUBSTITUTE(C9,""Sell_"",""""),Upgrades!$B$3:$B$13,0))*1.15^(COUNTIF(C$4:C8,SUBSTITUTE(C9,""Sell_"",""""))-COUNTIF(C$4:C8,""Sell_""&SUBS"&"TITUTE(C9,""Sell_"",""""))))/2),ROUNDUP(INDEX(Upgrades!$C$3:$C$13,MATCH(C9,Upgrades!$B$3:$B$13,0))*1.15^(COUNTIF(C$4:C8,C9)-COUNTIF(C$4:C8,""Sell_""&C9))))))"),20.0) -> 20 | H9: =IF(COUNTA(C9:C1648)=0,"",G9+IF(H8<0,H8)) -> 20 | I9: =IF(COUNTA(C9:C1648)=0,"",I8+IF(H9>0,H9,0)/F8) -> 93.873405 | J9: =IF(COUNTA(C9:C1648)=0,"",IF(I9>3600,TRUNC(I9/3600)&"h ","")&IF(I9>59,IF(AND(I9>3599,QUOTIENT(MOD(I9,3600),60)<10),"0","")&QUOTIENT(MOD(I9,3600),60)&"m ","")&IF(AND(I9>=10,MOD(I9,60)<10),"0","")&ROUNDDOWN(MOD(I9,60),0)&"s") -> 1m 33s | K9: =IF(COUNTA(C9:C1648)=0,"",K8+IF(H9>0,H9,0)) -> 1128 | L9: =IFS(AND(COUNTA(C9:C1648)=0,COUNTA(Q9:Q1648)=0),"",OR(AND(K9>=1000000000,OR(Y9>=1000000000,COUNTA(Q9:Q1648)=0)),OR(Y9>=1000000000,AND(COUNTA(C9:C1648)=0,P$3=TRUE))),AF$1, AND(K9<1000000000,COUNTA(C9:C1648)>0,P$3=FALSE),TRUNC(LARGE(W$4:W1648,COUNTIF(Y$4:Y1648,">"&K9)+1)+(K9-LARGE(Y$4:Y1648,COUNTIF(Y$4:Y1648,">"&K9)+1))/LARGE(T$4:T1648,COUNTIF(Y$4:Y1648,">"&K9)+1)-I9,5),1, TRUNC(W9-LARGE(I$4:I1648,COUNTIF(K$4:K1648,">"&Y9)+1)-(Y9-LARGE(K$4:K1648,COUNTIF(K$4:K1648,">"&Y9)+1))/LARGE(F$4:F1648,COUNTIF(K$4:K1648,">"&Y9)+1),5)) -> 0 | M9: =IFERROR(__xludf.DUMMYFUNCTION("IFS(AND(COUNTA(C9:C1644)=0,COUNTA(Q9:Q1644)=0),"""",OR(AND(K9>=1000000000,OR(Y9>=1000000000,COUNTA(Q9:Q1644)=0)),OR(Y9>=1000000000,AND(COUNTA(C9:C1644)=0,P$3=TRUE))), ROUNDDOWN((AB$1-AC$1)*MAX(INDEX(T$4:T1644,MATCH(LARGE(FILTER(Y$4:Y1644,Y$4:Y1644<1000000"&"000),1),Y$4:Y1644)),INDEX(F$4:F1644,MATCH(LARGE(FILTER(K$4:K1644,K$4:K1644<1000000000),1),K$4:K1644)))),AND(K9<1000000000,COUNTA(C9:C1644)>0,P$3=FALSE), ROUNDDOWN(INDEX(Y$4:Y1644,MATCH(LARGE(FILTER(W$4:W1644,W$4:W1644<=I9),1),W$4:W1644))+(I9-LARGE(FILTER("&"W$4:W1644,W$4:W1644<=I9),1))*INDEX(T$4:T1644,MATCH(LARGE(FILTER(W$4:W1644,W$4:W1644<=I9),1),W$4:W1644))-K9),1, ROUNDDOWN(Y9-INDEX(K$4:K1644,MATCH(LARGE(FILTER(I$4:I1644,I$4:I1644<=W9),1),I$4:I1644))-(W9-LARGE(FILTER(I$4:I1644,I$4:I1644<=W9),1))*INDEX(F$4:"&"F1644,MATCH(LARGE(FILTER(I$4:I1644,I$4:I1644<=W9),1),I$4:I1644))))"),0.0) -> 0 | N9: =IF(ABS(L9)>=10000,TEXT(ROUND(L9,1),"#.#")&IF(RIGHT(TEXT(ROUND(L9,1),"#.#"))=",","0",""),L9) -> 0 | O9: =IF(ABS(M9)<1000000,M9,IF(ABS(M9)<1000000000,TEXT(ROUND(M9/1000000,1),"#.#")&IF(RIGHT(TEXT(ROUND(M9/1000000,1),"#.#"))=",","0","")&"M",TEXT(ROUND(M9/1000000000,1),"#.#")&IF(RIGHT(TEXT(ROUND(M9/1000000000,1),"#.#"))=",","0","")&"B")) -> 0 | P9: =IF(COUNTA(Q9:Q1648)=0,"",COUNTIF(Q$4:Q9,Q9)-COUNTIF(Q$4:Q9,"Sell_"&Q9)) -> 3 | Q9: Cursor | R9: =IFERROR(__xludf.DUMMYFUNCTION("IF(COUNTA(Q9:Q1644)=0,"""",IF(ISBLANK(Q9),FALSE,IF(NOT(COUNTIF($AA$24:$AA$34,SUBSTITUTE(Q9,""Sell_"",""""))),1,IF(REGEXMATCH(Q9,""Sell_""),IF(COUNTIF(Q$4:Q9,SUBSTITUTE(Q9,""Sell_"",""""))-COUNTIF(Q$4:Q8,Q9)<1,1),FALSE))))"),FALSE) -> FALSE | S9: {=IF(COUNTA(Q9:Q1644)=0,"",SUM((COUNTIF(Q$4:Q9,Upgrades!$B$3:$B$13)-COUNTIF(Q$4:Q9,"Sell_"&Upgrades!$B$3:$B$13))*Upgrades!$D$3:$D$13))} -> 8.3 | T9: =IFERROR(__xludf.DUMMYFUNCTION("IF(COUNTA(Q9:Q1644)=0,"""",IF(REGEXMATCH(INDEX(FILTER(Q$4:Q9,Q$4:Q9<>""""),ROWS(FILTER(Q$4:Q9,Q$4:Q9<>""""))),""^Sell_""),INDEX(FILTER(T$4:T8,Q$4:Q8<>""""),ROWS(FILTER(Q$4:Q8,Q$4:Q8<>""""))),$AD$5+S9))"),18.3) -> 18.3 | U9: =IFERROR(__xludf.DUMMYFUNCTION("IF(COUNTA(Q9:Q1644)=0,"""",IF(Q9="""",0,IF(REGEXMATCH(Q9,""^Sell_""),-ROUNDDOWN(ROUNDUP(INDEX(Upgrades!$C$3:$C$13,MATCH(SUBSTITUTE(Q9,""Sell_"",""""),Upgrades!$B$3:$B$13,0))*1.15^(COUNTIF(Q$4:Q8,SUBSTITUTE(Q9,""Sell_"",""""))-COUNTIF(Q$4:Q8,""Sell_""&SUBS"&"TITUTE(Q9,""Sell_"",""""))))/2),ROUNDUP(INDEX(Upgrades!$C$3:$C$13,MATCH(Q9,Upgrades!$B$3:$B$13,0))*1.15^(COUNTIF(Q$4:Q8,Q9)-COUNTIF(Q$4:Q8,""Sell_""&Q9))))))"),20.0) -> 20 | V9: =IF(COUNTA(Q9:Q1648)=0,"",U9+IF(V8<0,V8)) -> 20 | W9: =IF(COUNTA(Q9:Q1648)=0,"",W8+IF(V9>0,V9,0)/T8) -> 93.873405 | X9: =IF(COUNTA(Q9:Q1648)=0,"",IF(W9>3600,TRUNC(W9/3600)&"h ","")&IF(W9>59,IF(AND(W9>3599,QUOTIENT(MOD(W9,3600),60)<10),"0","")&QUOTIENT(MOD(W9,3600),60)&"m ","")&IF(AND(W9>=10,MOD(W9,60)<10),"0","")&ROUNDDOWN(MOD(W9,60),0)&"s") -> 1m 33s | Y9: =IF(COUNTA(Q9:Q1648)=0,"",Y8+IF(V9>0,V9,0)) -> 1128 | AA9: INSTRUCTIONS: Create a copy of the spreadsheet.
B10: =IF(COUNTA(C10:C1649)=0,"",COUNTIF(C$4:C10,C10)-COUNTIF(C$4:C10,"Sell_"&C10)) -> 3 | C10: Farm | D10: =IFERROR(__xludf.DUMMYFUNCTION("IF(COUNTA(C10:C1644)=0,"""",IF(ISBLANK(C10),FALSE,IF(NOT(COUNTIF($AA$24:$AA$34,SUBSTITUTE(C10,""Sell_"",""""))),1,IF(REGEXMATCH(C10,""Sell_""),IF(COUNTIF(C$4:C10,SUBSTITUTE(C10,""Sell_"",""""))-COUNTIF(C$4:C9,C10)<1,1),FALSE))))"),FALSE) -> FALSE | E10: {=IF(COUNTA(C10:C1644)=0,"",SUM((COUNTIF(C$4:C10,Upgrades!$B$3:$B$13)-COUNTIF(C$4:C10,"Sell_"&Upgrades!$B$3:$B$13))*Upgrades!$D$3:$D$13))} -> 12.3 | F10: =IFERROR(__xludf.DUMMYFUNCTION("IF(COUNTA(C10:C1644)=0,"""",IF(REGEXMATCH(INDEX(FILTER(C$4:C10,C$4:C10<>""""),ROWS(FILTER(C$4:C10,C$4:C10<>""""))),""^Sell_""),INDEX(FILTER(F$4:F9,C$4:C9<>""""),ROWS(FILTER(C$4:C9,C$4:C9<>""""))),$AC$5+E10))"),22.3) -> 22.3 | G10: =IFERROR(__xludf.DUMMYFUNCTION("IF(COUNTA(C10:C1644)=0,"""",IF(C10="""",0,IF(REGEXMATCH(C10,""^Sell_""),-ROUNDDOWN(ROUNDUP(INDEX(Upgrades!$C$3:$C$13,MATCH(SUBSTITUTE(C10,""Sell_"",""""),Upgrades!$B$3:$B$13,0))*1.15^(COUNTIF(C$4:C9,SUBSTITUTE(C10,""Sell_"",""""))-COUNTIF(C$4:C9,""Sell_"""&"&SUBSTITUTE(C10,""Sell_"",""""))))/2),ROUNDUP(INDEX(Upgrades!$C$3:$C$13,MATCH(C10,Upgrades!$B$3:$B$13,0))*1.15^(COUNTIF(C$4:C9,C10)-COUNTIF(C$4:C9,""Sell_""&C10))))))"),662.0) -> 662 | H10: =IF(COUNTA(C10:C1649)=0,"",G10+IF(H9<0,H9)) -> 662 | I10: =IF(COUNTA(C10:C1649)=0,"",I9+IF(H10>0,H10,0)/F9) -> 130.04827 | J10: =IF(COUNTA(C10:C1649)=0,"",IF(I10>3600,TRUNC(I10/3600)&"h ","")&IF(I10>59,IF(AND(I10>3599,QUOTIENT(MOD(I10,3600),60)<10),"0","")&QUOTIENT(MOD(I10,3600),60)&"m ","")&IF(AND(I10>=10,MOD(I10,60)<10),"0","")&ROUNDDOWN(MOD(I10,60),0)&"s") -> 2m 10s | K10: =IF(COUNTA(C10:C1649)=0,"",K9+IF(H10>0,H10,0)) -> 1790 | L10: =IFS(AND(COUNTA(C10:C1649)=0,COUNTA(Q10:Q1649)=0),"",OR(AND(K10>=1000000000,OR(Y10>=1000000000,COUNTA(Q10:Q1649)=0)),OR(Y10>=1000000000,AND(COUNTA(C10:C1649)=0,P$3=TRUE))),AF$1, AND(K10<1000000000,COUNTA(C10:C1649)>0,P$3=FALSE),TRUNC(LARGE(W$4:W1649,COUNTIF(Y$4:Y1649,">"&K10)+1)+(K10-LARGE(Y$4:Y1649,COUNTIF(Y$4:Y1649,">"&K10)+1))/LARGE(T$4:T1649,COUNTIF(Y$4:Y1649,">"&K10)+1)-I10,5),1, TRUNC(W10-LARGE(I$4:I1649,COUNTIF(K$4:K1649,">"&Y10)+1)-(Y10-LARGE(K$4:K1649,COUNTIF(K$4:K1649,">"&Y10)+1))/LARGE(F$4:F1649,COUNTIF(K$4:K1649,">"&Y10)+1),5)) -> 0 | M10: =IFERROR(__xludf.DUMMYFUNCTION("IFS(AND(COUNTA(C10:C1644)=0,COUNTA(Q10:Q1644)=0),"""",OR(AND(K10>=1000000000,OR(Y10>=1000000000,COUNTA(Q10:Q1644)=0)),OR(Y10>=1000000000,AND(COUNTA(C10:C1644)=0,P$3=TRUE))), ROUNDDOWN((AB$1-AC$1)*MAX(INDEX(T$4:T1644,MATCH(LARGE(FILTER(Y$4:Y1644,Y$4:Y1644<"&"1000000000),1),Y$4:Y1644)),INDEX(F$4:F1644,MATCH(LARGE(FILTER(K$4:K1644,K$4:K1644<1000000000),1),K$4:K1644)))),AND(K10<1000000000,COUNTA(C10:C1644)>0,P$3=FALSE), ROUNDDOWN(INDEX(Y$4:Y1644,MATCH(LARGE(FILTER(W$4:W1644,W$4:W1644<=I10),1),W$4:W1644))+(I10-LA"&"RGE(FILTER(W$4:W1644,W$4:W1644<=I10),1))*INDEX(T$4:T1644,MATCH(LARGE(FILTER(W$4:W1644,W$4:W1644<=I10),1),W$4:W1644))-K10),1, ROUNDDOWN(Y10-INDEX(K$4:K1644,MATCH(LARGE(FILTER(I$4:I1644,I$4:I1644<=W10),1),I$4:I1644))-(W10-LARGE(FILTER(I$4:I1644,I$4:I1644<=W"&"10),1))*INDEX(F$4:F1644,MATCH(LARGE(FILTER(I$4:I1644,I$4:I1644<=W10),1),I$4:I1644))))"),0.0) -> 0 | N10: =IF(ABS(L10)>=10000,TEXT(ROUND(L10,1),"#.#")&IF(RIGHT(TEXT(ROUND(L10,1),"#.#"))=",","0",""),L10) -> 0 | O10: =IF(ABS(M10)<1000000,M10,IF(ABS(M10)<1000000000,TEXT(ROUND(M10/1000000,1),"#.#")&IF(RIGHT(TEXT(ROUND(M10/1000000,1),"#.#"))=",","0","")&"M",TEXT(ROUND(M10/1000000000,1),"#.#")&IF(RIGHT(TEXT(ROUND(M10/1000000000,1),"#.#"))=",","0","")&"B")) -> 0 | P10: =IF(COUNTA(Q10:Q1649)=0,"",COUNTIF(Q$4:Q10,Q10)-COUNTIF(Q$4:Q10,"Sell_"&Q10)) -> 3 | Q10: Farm | R10: =IFERROR(__xludf.DUMMYFUNCTION("IF(COUNTA(Q10:Q1644)=0,"""",IF(ISBLANK(Q10),FALSE,IF(NOT(COUNTIF($AA$24:$AA$34,SUBSTITUTE(Q10,""Sell_"",""""))),1,IF(REGEXMATCH(Q10,""Sell_""),IF(COUNTIF(Q$4:Q10,SUBSTITUTE(Q10,""Sell_"",""""))-COUNTIF(Q$4:Q9,Q10)<1,1),FALSE))))"),FALSE) -> FALSE | S10: {=IF(COUNTA(Q10:Q1644)=0,"",SUM((COUNTIF(Q$4:Q10,Upgrades!$B$3:$B$13)-COUNTIF(Q$4:Q10,"Sell_"&Upgrades!$B$3:$B$13))*Upgrades!$D$3:$D$13))} -> 12.3 | T10: =IFERROR(__xludf.DUMMYFUNCTION("IF(COUNTA(Q10:Q1644)=0,"""",IF(REGEXMATCH(INDEX(FILTER(Q$4:Q10,Q$4:Q10<>""""),ROWS(FILTER(Q$4:Q10,Q$4:Q10<>""""))),""^Sell_""),INDEX(FILTER(T$4:T9,Q$4:Q9<>""""),ROWS(FILTER(Q$4:Q9,Q$4:Q9<>""""))),$AD$5+S10))"),22.3) -> 22.3 | U10: =IFERROR(__xludf.DUMMYFUNCTION("IF(COUNTA(Q10:Q1644)=0,"""",IF(Q10="""",0,IF(REGEXMATCH(Q10,""^Sell_""),-ROUNDDOWN(ROUNDUP(INDEX(Upgrades!$C$3:$C$13,MATCH(SUBSTITUTE(Q10,""Sell_"",""""),Upgrades!$B$3:$B$13,0))*1.15^(COUNTIF(Q$4:Q9,SUBSTITUTE(Q10,""Sell_"",""""))-COUNTIF(Q$4:Q9,""Sell_"""&"&SUBSTITUTE(Q10,""Sell_"",""""))))/2),ROUNDUP(INDEX(Upgrades!$C$3:$C$13,MATCH(Q10,Upgrades!$B$3:$B$13,0))*1.15^(COUNTIF(Q$4:Q9,Q10)-COUNTIF(Q$4:Q9,""Sell_""&Q10))))))"),662.0) -> 662 | V10: =IF(COUNTA(Q10:Q1649)=0,"",U10+IF(V9<0,V9)) -> 662 | W10: =IF(COUNTA(Q10:Q1649)=0,"",W9+IF(V10>0,V10,0)/T9) -> 130.04827 | X10: =IF(COUNTA(Q10:Q1649)=0,"",IF(W10>3600,TRUNC(W10/3600)&"h ","")&IF(W10>59,IF(AND(W10>3599,QUOTIENT(MOD(W10,3600),60)<10),"0","")&QUOTIENT(MOD(W10,3600),60)&"m ","")&IF(AND(W10>=10,MOD(W10,60)<10),"0","")&ROUNDDOWN(MOD(W10,60),0)&"s") -> 2m 10s | Y10: =IF(COUNTA(Q10:Q1649)=0,"",Y9+IF(V10>0,V10,0)) -> 1790 | AA10: You can change the "New Route" actions, adding, removing,
B11: =IF(COUNTA(C11:C1650)=0,"",COUNTIF(C$4:C11,C11)-COUNTIF(C$4:C11,"Sell_"&C11)) -> 1 | C11: Grandma | D11: =IFERROR(__xludf.DUMMYFUNCTION("IF(COUNTA(C11:C1644)=0,"""",IF(ISBLANK(C11),FALSE,IF(NOT(COUNTIF($AA$24:$AA$34,SUBSTITUTE(C11,""Sell_"",""""))),1,IF(REGEXMATCH(C11,""Sell_""),IF(COUNTIF(C$4:C11,SUBSTITUTE(C11,""Sell_"",""""))-COUNTIF(C$4:C10,C11)<1,1),FALSE))))"),FALSE) -> FALSE | E11: {=IF(COUNTA(C11:C1644)=0,"",SUM((COUNTIF(C$4:C11,Upgrades!$B$3:$B$13)-COUNTIF(C$4:C11,"Sell_"&Upgrades!$B$3:$B$13))*Upgrades!$D$3:$D$13))} -> 12.8 | F11: =IFERROR(__xludf.DUMMYFUNCTION("IF(COUNTA(C11:C1644)=0,"""",IF(REGEXMATCH(INDEX(FILTER(C$4:C11,C$4:C11<>""""),ROWS(FILTER(C$4:C11,C$4:C11<>""""))),""^Sell_""),INDEX(FILTER(F$4:F10,C$4:C10<>""""),ROWS(FILTER(C$4:C10,C$4:C10<>""""))),$AC$5+E11))"),22.8) -> 22.8 | G11: =IFERROR(__xludf.DUMMYFUNCTION("IF(COUNTA(C11:C1644)=0,"""",IF(C11="""",0,IF(REGEXMATCH(C11,""^Sell_""),-ROUNDDOWN(ROUNDUP(INDEX(Upgrades!$C$3:$C$13,MATCH(SUBSTITUTE(C11,""Sell_"",""""),Upgrades!$B$3:$B$13,0))*1.15^(COUNTIF(C$4:C10,SUBSTITUTE(C11,""Sell_"",""""))-COUNTIF(C$4:C10,""Sell_"&"""&SUBSTITUTE(C11,""Sell_"",""""))))/2),ROUNDUP(INDEX(Upgrades!$C$3:$C$13,MATCH(C11,Upgrades!$B$3:$B$13,0))*1.15^(COUNTIF(C$4:C10,C11)-COUNTIF(C$4:C10,""Sell_""&C11))))))"),100.0) -> 100 | H11: =IF(COUNTA(C11:C1650)=0,"",G11+IF(H10<0,H10)) -> 100 | I11: =IF(COUNTA(C11:C1650)=0,"",I10+IF(H11>0,H11,0)/F10) -> 134.53257 | J11: =IF(COUNTA(C11:C1650)=0,"",IF(I11>3600,TRUNC(I11/3600)&"h ","")&IF(I11>59,IF(AND(I11>3599,QUOTIENT(MOD(I11,3600),60)<10),"0","")&QUOTIENT(MOD(I11,3600),60)&"m ","")&IF(AND(I11>=10,MOD(I11,60)<10),"0","")&ROUNDDOWN(MOD(I11,60),0)&"s") -> 2m 14s | K11: =IF(COUNTA(C11:C1650)=0,"",K10+IF(H11>0,H11,0)) -> 1890 | L11: =IFS(AND(COUNTA(C11:C1650)=0,COUNTA(Q11:Q1650)=0),"",OR(AND(K11>=1000000000,OR(Y11>=1000000000,COUNTA(Q11:Q1650)=0)),OR(Y11>=1000000000,AND(COUNTA(C11:C1650)=0,P$3=TRUE))),AF$1, AND(K11<1000000000,COUNTA(C11:C1650)>0,P$3=FALSE),TRUNC(LARGE(W$4:W1650,COUNTIF(Y$4:Y1650,">"&K11)+1)+(K11-LARGE(Y$4:Y1650,COUNTIF(Y$4:Y1650,">"&K11)+1))/LARGE(T$4:T1650,COUNTIF(Y$4:Y1650,">"&K11)+1)-I11,5),1, TRUNC(W11-LARGE(I$4:I1650,COUNTIF(K$4:K1650,">"&Y11)+1)-(Y11-LARGE(K$4:K1650,COUNTIF(K$4:K1650,">"&Y11)+1))/LARGE(F$4:F1650,COUNTIF(K$4:K1650,">"&Y11)+1),5)) -> 0 | M11: =IFERROR(__xludf.DUMMYFUNCTION("IFS(AND(COUNTA(C11:C1644)=0,COUNTA(Q11:Q1644)=0),"""",OR(AND(K11>=1000000000,OR(Y11>=1000000000,COUNTA(Q11:Q1644)=0)),OR(Y11>=1000000000,AND(COUNTA(C11:C1644)=0,P$3=TRUE))), ROUNDDOWN((AB$1-AC$1)*MAX(INDEX(T$4:T1644,MATCH(LARGE(FILTER(Y$4:Y1644,Y$4:Y1644<"&"1000000000),1),Y$4:Y1644)),INDEX(F$4:F1644,MATCH(LARGE(FILTER(K$4:K1644,K$4:K1644<1000000000),1),K$4:K1644)))),AND(K11<1000000000,COUNTA(C11:C1644)>0,P$3=FALSE), ROUNDDOWN(INDEX(Y$4:Y1644,MATCH(LARGE(FILTER(W$4:W1644,W$4:W1644<=I11),1),W$4:W1644))+(I11-LA"&"RGE(FILTER(W$4:W1644,W$4:W1644<=I11),1))*INDEX(T$4:T1644,MATCH(LARGE(FILTER(W$4:W1644,W$4:W1644<=I11),1),W$4:W1644))-K11),1, ROUNDDOWN(Y11-INDEX(K$4:K1644,MATCH(LARGE(FILTER(I$4:I1644,I$4:I1644<=W11),1),I$4:I1644))-(W11-LARGE(FILTER(I$4:I1644,I$4:I1644<=W"&"11),1))*INDEX(F$4:F1644,MATCH(LARGE(FILTER(I$4:I1644,I$4:I1644<=W11),1),I$4:I1644))))"),0.0) -> 0 | N11: =IF(ABS(L11)>=10000,TEXT(ROUND(L11,1),"#.#")&IF(RIGHT(TEXT(ROUND(L11,1),"#.#"))=",","0",""),L11) -> 0 | O11: =IF(ABS(M11)<1000000,M11,IF(ABS(M11)<1000000000,TEXT(ROUND(M11/1000000,1),"#.#")&IF(RIGHT(TEXT(ROUND(M11/1000000,1),"#.#"))=",","0","")&"M",TEXT(ROUND(M11/1000000000,1),"#.#")&IF(RIGHT(TEXT(ROUND(M11/1000000000,1),"#.#"))=",","0","")&"B")) -> 0 | P11: =IF(COUNTA(Q11:Q1650)=0,"",COUNTIF(Q$4:Q11,Q11)-COUNTIF(Q$4:Q11,"Sell_"&Q11)) -> 1 | Q11: Grandma | R11: =IFERROR(__xludf.DUMMYFUNCTION("IF(COUNTA(Q11:Q1644)=0,"""",IF(ISBLANK(Q11),FALSE,IF(NOT(COUNTIF($AA$24:$AA$34,SUBSTITUTE(Q11,""Sell_"",""""))),1,IF(REGEXMATCH(Q11,""Sell_""),IF(COUNTIF(Q$4:Q11,SUBSTITUTE(Q11,""Sell_"",""""))-COUNTIF(Q$4:Q10,Q11)<1,1),FALSE))))"),FALSE) -> FALSE | S11: {=IF(COUNTA(Q11:Q1644)=0,"",SUM((COUNTIF(Q$4:Q11,Upgrades!$B$3:$B$13)-COUNTIF(Q$4:Q11,"Sell_"&Upgrades!$B$3:$B$13))*Upgrades!$D$3:$D$13))} -> 12.8 | T11: =IFERROR(__xludf.DUMMYFUNCTION("IF(COUNTA(Q11:Q1644)=0,"""",IF(REGEXMATCH(INDEX(FILTER(Q$4:Q11,Q$4:Q11<>""""),ROWS(FILTER(Q$4:Q11,Q$4:Q11<>""""))),""^Sell_""),INDEX(FILTER(T$4:T10,Q$4:Q10<>""""),ROWS(FILTER(Q$4:Q10,Q$4:Q10<>""""))),$AD$5+S11))"),22.8) -> 22.8 | U11: =IFERROR(__xludf.DUMMYFUNCTION("IF(COUNTA(Q11:Q1644)=0,"""",IF(Q11="""",0,IF(REGEXMATCH(Q11,""^Sell_""),-ROUNDDOWN(ROUNDUP(INDEX(Upgrades!$C$3:$C$13,MATCH(SUBSTITUTE(Q11,""Sell_"",""""),Upgrades!$B$3:$B$13,0))*1.15^(COUNTIF(Q$4:Q10,SUBSTITUTE(Q11,""Sell_"",""""))-COUNTIF(Q$4:Q10,""Sell_"&"""&SUBSTITUTE(Q11,""Sell_"",""""))))/2),ROUNDUP(INDEX(Upgrades!$C$3:$C$13,MATCH(Q11,Upgrades!$B$3:$B$13,0))*1.15^(COUNTIF(Q$4:Q10,Q11)-COUNTIF(Q$4:Q10,""Sell_""&Q11))))))"),100.0) -> 100 | V11: =IF(COUNTA(Q11:Q1650)=0,"",U11+IF(V10<0,V10)) -> 100 | W11: =IF(COUNTA(Q11:Q1650)=0,"",W10+IF(V11>0,V11,0)/T10) -> 134.53257 | X11: =IF(COUNTA(Q11:Q1650)=0,"",IF(W11>3600,TRUNC(W11/3600)&"h ","")&IF(W11>59,IF(AND(W11>3599,QUOTIENT(MOD(W11,3600),60)<10),"0","")&QUOTIENT(MOD(W11,3600),60)&"m ","")&IF(AND(W11>=10,MOD(W11,60)<10),"0","")&ROUNDDOWN(MOD(W11,60),0)&"s") -> 2m 14s | Y11: =IF(COUNTA(Q11:Q1650)=0,"",Y10+IF(V11>0,V11,0)) -> 1890 | AA11: switching them and see if you get better numbers over time.
B12: =IF(COUNTA(C12:C1651)=0,"",COUNTIF(C$4:C12,C12)-COUNTIF(C$4:C12,"Sell_"&C12)) -> 4 | C12: Farm | D12: =IFERROR(__xludf.DUMMYFUNCTION("IF(COUNTA(C12:C1644)=0,"""",IF(ISBLANK(C12),FALSE,IF(NOT(COUNTIF($AA$24:$AA$34,SUBSTITUTE(C12,""Sell_"",""""))),1,IF(REGEXMATCH(C12,""Sell_""),IF(COUNTIF(C$4:C12,SUBSTITUTE(C12,""Sell_"",""""))-COUNTIF(C$4:C11,C12)<1,1),FALSE))))"),FALSE) -> FALSE | E12: {=IF(COUNTA(C12:C1644)=0,"",SUM((COUNTIF(C$4:C12,Upgrades!$B$3:$B$13)-COUNTIF(C$4:C12,"Sell_"&Upgrades!$B$3:$B$13))*Upgrades!$D$3:$D$13))} -> 16.8 | F12: =IFERROR(__xludf.DUMMYFUNCTION("IF(COUNTA(C12:C1644)=0,"""",IF(REGEXMATCH(INDEX(FILTER(C$4:C12,C$4:C12<>""""),ROWS(FILTER(C$4:C12,C$4:C12<>""""))),""^Sell_""),INDEX(FILTER(F$4:F11,C$4:C11<>""""),ROWS(FILTER(C$4:C11,C$4:C11<>""""))),$AC$5+E12))"),26.8) -> 26.8 | G12: =IFERROR(__xludf.DUMMYFUNCTION("IF(COUNTA(C12:C1644)=0,"""",IF(C12="""",0,IF(REGEXMATCH(C12,""^Sell_""),-ROUNDDOWN(ROUNDUP(INDEX(Upgrades!$C$3:$C$13,MATCH(SUBSTITUTE(C12,""Sell_"",""""),Upgrades!$B$3:$B$13,0))*1.15^(COUNTIF(C$4:C11,SUBSTITUTE(C12,""Sell_"",""""))-COUNTIF(C$4:C11,""Sell_"&"""&SUBSTITUTE(C12,""Sell_"",""""))))/2),ROUNDUP(INDEX(Upgrades!$C$3:$C$13,MATCH(C12,Upgrades!$B$3:$B$13,0))*1.15^(COUNTIF(C$4:C11,C12)-COUNTIF(C$4:C11,""Sell_""&C12))))))"),761.0) -> 761 | H12: =IF(COUNTA(C12:C1651)=0,"",G12+IF(H11<0,H11)) -> 761 | I12: =IF(COUNTA(C12:C1651)=0,"",I11+IF(H12>0,H12,0)/F11) -> 167.90977 | J12: =IF(COUNTA(C12:C1651)=0,"",IF(I12>3600,TRUNC(I12/3600)&"h ","")&IF(I12>59,IF(AND(I12>3599,QUOTIENT(MOD(I12,3600),60)<10),"0","")&QUOTIENT(MOD(I12,3600),60)&"m ","")&IF(AND(I12>=10,MOD(I12,60)<10),"0","")&ROUNDDOWN(MOD(I12,60),0)&"s") -> 2m 47s | K12: =IF(COUNTA(C12:C1651)=0,"",K11+IF(H12>0,H12,0)) -> 2651 | L12: =IFS(AND(COUNTA(C12:C1651)=0,COUNTA(Q12:Q1651)=0),"",OR(AND(K12>=1000000000,OR(Y12>=1000000000,COUNTA(Q12:Q1651)=0)),OR(Y12>=1000000000,AND(COUNTA(C12:C1651)=0,P$3=TRUE))),AF$1, AND(K12<1000000000,COUNTA(C12:C1651)>0,P$3=FALSE),TRUNC(LARGE(W$4:W1651,COUNTIF(Y$4:Y1651,">"&K12)+1)+(K12-LARGE(Y$4:Y1651,COUNTIF(Y$4:Y1651,">"&K12)+1))/LARGE(T$4:T1651,COUNTIF(Y$4:Y1651,">"&K12)+1)-I12,5),1, TRUNC(W12-LARGE(I$4:I1651,COUNTIF(K$4:K1651,">"&Y12)+1)-(Y12-LARGE(K$4:K1651,COUNTIF(K$4:K1651,">"&Y12)+1))/LARGE(F$4:F1651,COUNTIF(K$4:K1651,">"&Y12)+1),5)) -> 0 | M12: =IFERROR(__xludf.DUMMYFUNCTION("IFS(AND(COUNTA(C12:C1644)=0,COUNTA(Q12:Q1644)=0),"""",OR(AND(K12>=1000000000,OR(Y12>=1000000000,COUNTA(Q12:Q1644)=0)),OR(Y12>=1000000000,AND(COUNTA(C12:C1644)=0,P$3=TRUE))), ROUNDDOWN((AB$1-AC$1)*MAX(INDEX(T$4:T1644,MATCH(LARGE(FILTER(Y$4:Y1644,Y$4:Y1644<"&"1000000000),1),Y$4:Y1644)),INDEX(F$4:F1644,MATCH(LARGE(FILTER(K$4:K1644,K$4:K1644<1000000000),1),K$4:K1644)))),AND(K12<1000000000,COUNTA(C12:C1644)>0,P$3=FALSE), ROUNDDOWN(INDEX(Y$4:Y1644,MATCH(LARGE(FILTER(W$4:W1644,W$4:W1644<=I12),1),W$4:W1644))+(I12-LA"&"RGE(FILTER(W$4:W1644,W$4:W1644<=I12),1))*INDEX(T$4:T1644,MATCH(LARGE(FILTER(W$4:W1644,W$4:W1644<=I12),1),W$4:W1644))-K12),1, ROUNDDOWN(Y12-INDEX(K$4:K1644,MATCH(LARGE(FILTER(I$4:I1644,I$4:I1644<=W12),1),I$4:I1644))-(W12-LARGE(FILTER(I$4:I1644,I$4:I1644<=W"&"12),1))*INDEX(F$4:F1644,MATCH(LARGE(FILTER(I$4:I1644,I$4:I1644<=W12),1),I$4:I1644))))"),0.0) -> 0 | N12: =IF(ABS(L12)>=10000,TEXT(ROUND(L12,1),"#.#")&IF(RIGHT(TEXT(ROUND(L12,1),"#.#"))=",","0",""),L12) -> 0 | O12: =IF(ABS(M12)<1000000,M12,IF(ABS(M12)<1000000000,TEXT(ROUND(M12/1000000,1),"#.#")&IF(RIGHT(TEXT(ROUND(M12/1000000,1),"#.#"))=",","0","")&"M",TEXT(ROUND(M12/1000000000,1),"#.#")&IF(RIGHT(TEXT(ROUND(M12/1000000000,1),"#.#"))=",","0","")&"B")) -> 0 | P12: =IF(COUNTA(Q12:Q1651)=0,"",COUNTIF(Q$4:Q12,Q12)-COUNTIF(Q$4:Q12,"Sell_"&Q12)) -> 4 | Q12: Farm | R12: =IFERROR(__xludf.DUMMYFUNCTION("IF(COUNTA(Q12:Q1644)=0,"""",IF(ISBLANK(Q12),FALSE,IF(NOT(COUNTIF($AA$24:$AA$34,SUBSTITUTE(Q12,""Sell_"",""""))),1,IF(REGEXMATCH(Q12,""Sell_""),IF(COUNTIF(Q$4:Q12,SUBSTITUTE(Q12,""Sell_"",""""))-COUNTIF(Q$4:Q11,Q12)<1,1),FALSE))))"),FALSE) -> FALSE | S12: {=IF(COUNTA(Q12:Q1644)=0,"",SUM((COUNTIF(Q$4:Q12,Upgrades!$B$3:$B$13)-COUNTIF(Q$4:Q12,"Sell_"&Upgrades!$B$3:$B$13))*Upgrades!$D$3:$D$13))} -> 16.8 | T12: =IFERROR(__xludf.DUMMYFUNCTION("IF(COUNTA(Q12:Q1644)=0,"""",IF(REGEXMATCH(INDEX(FILTER(Q$4:Q12,Q$4:Q12<>""""),ROWS(FILTER(Q$4:Q12,Q$4:Q12<>""""))),""^Sell_""),INDEX(FILTER(T$4:T11,Q$4:Q11<>""""),ROWS(FILTER(Q$4:Q11,Q$4:Q11<>""""))),$AD$5+S12))"),26.8) -> 26.8 | U12: =IFERROR(__xludf.DUMMYFUNCTION("IF(COUNTA(Q12:Q1644)=0,"""",IF(Q12="""",0,IF(REGEXMATCH(Q12,""^Sell_""),-ROUNDDOWN(ROUNDUP(INDEX(Upgrades!$C$3:$C$13,MATCH(SUBSTITUTE(Q12,""Sell_"",""""),Upgrades!$B$3:$B$13,0))*1.15^(COUNTIF(Q$4:Q11,SUBSTITUTE(Q12,""Sell_"",""""))-COUNTIF(Q$4:Q11,""Sell_"&"""&SUBSTITUTE(Q12,""Sell_"",""""))))/2),ROUNDUP(INDEX(Upgrades!$C$3:$C$13,MATCH(Q12,Upgrades!$B$3:$B$13,0))*1.15^(COUNTIF(Q$4:Q11,Q12)-COUNTIF(Q$4:Q11,""Sell_""&Q12))))))"),761.0) -> 761 | V12: =IF(COUNTA(Q12:Q1651)=0,"",U12+IF(V11<0,V11)) -> 761 | W12: =IF(COUNTA(Q12:Q1651)=0,"",W11+IF(V12>0,V12,0)/T11) -> 167.90977 | X12: =IF(COUNTA(Q12:Q1651)=0,"",IF(W12>3600,TRUNC(W12/3600)&"h ","")&IF(W12>59,IF(AND(W12>3599,QUOTIENT(MOD(W12,3600),60)<10),"0","")&QUOTIENT(MOD(W12,3600),60)&"m ","")&IF(AND(W12>=10,MOD(W12,60)<10),"0","")&ROUNDDOWN(MOD(W12,60),0)&"s") -> 2m 47s | Y12: =IF(COUNTA(Q12:Q1651)=0,"",Y11+IF(V12>0,V12,0)) -> 2651 | AA12: You will have real-time cookies and time comparisons.
B13: =IF(COUNTA(C13:C1652)=0,"",COUNTIF(C$4:C13,C13)-COUNTIF(C$4:C13,"Sell_"&C13)) -> 4 | C13: Cursor | D13: =IFERROR(__xludf.DUMMYFUNCTION("IF(COUNTA(C13:C1644)=0,"""",IF(ISBLANK(C13),FALSE,IF(NOT(COUNTIF($AA$24:$AA$34,SUBSTITUTE(C13,""Sell_"",""""))),1,IF(REGEXMATCH(C13,""Sell_""),IF(COUNTIF(C$4:C13,SUBSTITUTE(C13,""Sell_"",""""))-COUNTIF(C$4:C12,C13)<1,1),FALSE))))"),FALSE) -> FALSE | E13: {=IF(COUNTA(C13:C1644)=0,"",SUM((COUNTIF(C$4:C13,Upgrades!$B$3:$B$13)-COUNTIF(C$4:C13,"Sell_"&Upgrades!$B$3:$B$13))*Upgrades!$D$3:$D$13))} -> 16.9 | F13: =IFERROR(__xludf.DUMMYFUNCTION("IF(COUNTA(C13:C1644)=0,"""",IF(REGEXMATCH(INDEX(FILTER(C$4:C13,C$4:C13<>""""),ROWS(FILTER(C$4:C13,C$4:C13<>""""))),""^Sell_""),INDEX(FILTER(F$4:F12,C$4:C12<>""""),ROWS(FILTER(C$4:C12,C$4:C12<>""""))),$AC$5+E13))"),26.9) -> 26.9 | G13: =IFERROR(__xludf.DUMMYFUNCTION("IF(COUNTA(C13:C1644)=0,"""",IF(C13="""",0,IF(REGEXMATCH(C13,""^Sell_""),-ROUNDDOWN(ROUNDUP(INDEX(Upgrades!$C$3:$C$13,MATCH(SUBSTITUTE(C13,""Sell_"",""""),Upgrades!$B$3:$B$13,0))*1.15^(COUNTIF(C$4:C12,SUBSTITUTE(C13,""Sell_"",""""))-COUNTIF(C$4:C12,""Sell_"&"""&SUBSTITUTE(C13,""Sell_"",""""))))/2),ROUNDUP(INDEX(Upgrades!$C$3:$C$13,MATCH(C13,Upgrades!$B$3:$B$13,0))*1.15^(COUNTIF(C$4:C12,C13)-COUNTIF(C$4:C12,""Sell_""&C13))))))"),23.0) -> 23 | H13: =IF(COUNTA(C13:C1652)=0,"",G13+IF(H12<0,H12)) -> 23 | I13: =IF(COUNTA(C13:C1652)=0,"",I12+IF(H13>0,H13,0)/F12) -> 168.76798 | J13: =IF(COUNTA(C13:C1652)=0,"",IF(I13>3600,TRUNC(I13/3600)&"h ","")&IF(I13>59,IF(AND(I13>3599,QUOTIENT(MOD(I13,3600),60)<10),"0","")&QUOTIENT(MOD(I13,3600),60)&"m ","")&IF(AND(I13>=10,MOD(I13,60)<10),"0","")&ROUNDDOWN(MOD(I13,60),0)&"s") -> 2m 48s | K13: =IF(COUNTA(C13:C1652)=0,"",K12+IF(H13>0,H13,0)) -> 2674 | L13: =IFS(AND(COUNTA(C13:C1652)=0,COUNTA(Q13:Q1652)=0),"",OR(AND(K13>=1000000000,OR(Y13>=1000000000,COUNTA(Q13:Q1652)=0)),OR(Y13>=1000000000,AND(COUNTA(C13:C1652)=0,P$3=TRUE))),AF$1, AND(K13<1000000000,COUNTA(C13:C1652)>0,P$3=FALSE),TRUNC(LARGE(W$4:W1652,COUNTIF(Y$4:Y1652,">"&K13)+1)+(K13-LARGE(Y$4:Y1652,COUNTIF(Y$4:Y1652,">"&K13)+1))/LARGE(T$4:T1652,COUNTIF(Y$4:Y1652,">"&K13)+1)-I13,5),1, TRUNC(W13-LARGE(I$4:I1652,COUNTIF(K$4:K1652,">"&Y13)+1)-(Y13-LARGE(K$4:K1652,COUNTIF(K$4:K1652,">"&Y13)+1))/LARGE(F$4:F1652,COUNTIF(K$4:K1652,">"&Y13)+1),5)) -> 0 | M13: =IFERROR(__xludf.DUMMYFUNCTION("IFS(AND(COUNTA(C13:C1644)=0,COUNTA(Q13:Q1644)=0),"""",OR(AND(K13>=1000000000,OR(Y13>=1000000000,COUNTA(Q13:Q1644)=0)),OR(Y13>=1000000000,AND(COUNTA(C13:C1644)=0,P$3=TRUE))), ROUNDDOWN((AB$1-AC$1)*MAX(INDEX(T$4:T1644,MATCH(LARGE(FILTER(Y$4:Y1644,Y$4:Y1644<"&"1000000000),1),Y$4:Y1644)),INDEX(F$4:F1644,MATCH(LARGE(FILTER(K$4:K1644,K$4:K1644<1000000000),1),K$4:K1644)))),AND(K13<1000000000,COUNTA(C13:C1644)>0,P$3=FALSE), ROUNDDOWN(INDEX(Y$4:Y1644,MATCH(LARGE(FILTER(W$4:W1644,W$4:W1644<=I13),1),W$4:W1644))+(I13-LA"&"RGE(FILTER(W$4:W1644,W$4:W1644<=I13),1))*INDEX(T$4:T1644,MATCH(LARGE(FILTER(W$4:W1644,W$4:W1644<=I13),1),W$4:W1644))-K13),1, ROUNDDOWN(Y13-INDEX(K$4:K1644,MATCH(LARGE(FILTER(I$4:I1644,I$4:I1644<=W13),1),I$4:I1644))-(W13-LARGE(FILTER(I$4:I1644,I$4:I1644<=W"&"13),1))*INDEX(F$4:F1644,MATCH(LARGE(FILTER(I$4:I1644,I$4:I1644<=W13),1),I$4:I1644))))"),0.0) -> 0 | N13: =IF(ABS(L13)>=10000,TEXT(ROUND(L13,1),"#.#")&IF(RIGHT(TEXT(ROUND(L13,1),"#.#"))=",","0",""),L13) -> 0 | O13: =IF(ABS(M13)<1000000,M13,IF(ABS(M13)<1000000000,TEXT(ROUND(M13/1000000,1),"#.#")&IF(RIGHT(TEXT(ROUND(M13/1000000,1),"#.#"))=",","0","")&"M",TEXT(ROUND(M13/1000000000,1),"#.#")&IF(RIGHT(TEXT(ROUND(M13/1000000000,1),"#.#"))=",","0","")&"B")) -> 0 | P13: =IF(COUNTA(Q13:Q1652)=0,"",COUNTIF(Q$4:Q13,Q13)-COUNTIF(Q$4:Q13,"Sell_"&Q13)) -> 4 | Q13: Cursor | R13: =IFERROR(__xludf.DUMMYFUNCTION("IF(COUNTA(Q13:Q1644)=0,"""",IF(ISBLANK(Q13),FALSE,IF(NOT(COUNTIF($AA$24:$AA$34,SUBSTITUTE(Q13,""Sell_"",""""))),1,IF(REGEXMATCH(Q13,""Sell_""),IF(COUNTIF(Q$4:Q13,SUBSTITUTE(Q13,""Sell_"",""""))-COUNTIF(Q$4:Q12,Q13)<1,1),FALSE))))"),FALSE) -> FALSE | S13: {=IF(COUNTA(Q13:Q1644)=0,"",SUM((COUNTIF(Q$4:Q13,Upgrades!$B$3:$B$13)-COUNTIF(Q$4:Q13,"Sell_"&Upgrades!$B$3:$B$13))*Upgrades!$D$3:$D$13))} -> 16.9 | T13: =IFERROR(__xludf.DUMMYFUNCTION("IF(COUNTA(Q13:Q1644)=0,"""",IF(REGEXMATCH(INDEX(FILTER(Q$4:Q13,Q$4:Q13<>""""),ROWS(FILTER(Q$4:Q13,Q$4:Q13<>""""))),""^Sell_""),INDEX(FILTER(T$4:T12,Q$4:Q12<>""""),ROWS(FILTER(Q$4:Q12,Q$4:Q12<>""""))),$AD$5+S13))"),26.9) -> 26.9 | U13: =IFERROR(__xludf.DUMMYFUNCTION("IF(COUNTA(Q13:Q1644)=0,"""",IF(Q13="""",0,IF(REGEXMATCH(Q13,""^Sell_""),-ROUNDDOWN(ROUNDUP(INDEX(Upgrades!$C$3:$C$13,MATCH(SUBSTITUTE(Q13,""Sell_"",""""),Upgrades!$B$3:$B$13,0))*1.15^(COUNTIF(Q$4:Q12,SUBSTITUTE(Q13,""Sell_"",""""))-COUNTIF(Q$4:Q12,""Sell_"&"""&SUBSTITUTE(Q13,""Sell_"",""""))))/2),ROUNDUP(INDEX(Upgrades!$C$3:$C$13,MATCH(Q13,Upgrades!$B$3:$B$13,0))*1.15^(COUNTIF(Q$4:Q12,Q13)-COUNTIF(Q$4:Q12,""Sell_""&Q13))))))"),23.0) -> 23 | V13: =IF(COUNTA(Q13:Q1652)=0,"",U13+IF(V12<0,V12)) -> 23 | W13: =IF(COUNTA(Q13:Q1652)=0,"",W12+IF(V13>0,V13,0)/T12) -> 168.76798 | X13: =IF(COUNTA(Q13:Q1652)=0,"",IF(W13>3600,TRUNC(W13/3600)&"h ","")&IF(W13>59,IF(AND(W13>3599,QUOTIENT(MOD(W13,3600),60)<10),"0","")&QUOTIENT(MOD(W13,3600),60)&"m ","")&IF(AND(W13>=10,MOD(W13,60)<10),"0","")&ROUNDDOWN(MOD(W13,60),0)&"s") -> 2m 48s | Y13: =IF(COUNTA(Q13:Q1652)=0,"",Y12+IF(V13>0,V13,0)) -> 2674
B14: =IF(COUNTA(C14:C1653)=0,"",COUNTIF(C$4:C14,C14)-COUNTIF(C$4:C14,"Sell_"&C14)) -> 2 | C14: Grandma | D14: =IFERROR(__xludf.DUMMYFUNCTION("IF(COUNTA(C14:C1644)=0,"""",IF(ISBLANK(C14),FALSE,IF(NOT(COUNTIF($AA$24:$AA$34,SUBSTITUTE(C14,""Sell_"",""""))),1,IF(REGEXMATCH(C14,""Sell_""),IF(COUNTIF(C$4:C14,SUBSTITUTE(C14,""Sell_"",""""))-COUNTIF(C$4:C13,C14)<1,1),FALSE))))"),FALSE) -> FALSE | E14: {=IF(COUNTA(C14:C1644)=0,"",SUM((COUNTIF(C$4:C14,Upgrades!$B$3:$B$13)-COUNTIF(C$4:C14,"Sell_"&Upgrades!$B$3:$B$13))*Upgrades!$D$3:$D$13))} -> 17.4 | F14: =IFERROR(__xludf.DUMMYFUNCTION("IF(COUNTA(C14:C1644)=0,"""",IF(REGEXMATCH(INDEX(FILTER(C$4:C14,C$4:C14<>""""),ROWS(FILTER(C$4:C14,C$4:C14<>""""))),""^Sell_""),INDEX(FILTER(F$4:F13,C$4:C13<>""""),ROWS(FILTER(C$4:C13,C$4:C13<>""""))),$AC$5+E14))"),27.4) -> 27.4 | G14: =IFERROR(__xludf.DUMMYFUNCTION("IF(COUNTA(C14:C1644)=0,"""",IF(C14="""",0,IF(REGEXMATCH(C14,""^Sell_""),-ROUNDDOWN(ROUNDUP(INDEX(Upgrades!$C$3:$C$13,MATCH(SUBSTITUTE(C14,""Sell_"",""""),Upgrades!$B$3:$B$13,0))*1.15^(COUNTIF(C$4:C13,SUBSTITUTE(C14,""Sell_"",""""))-COUNTIF(C$4:C13,""Sell_"&"""&SUBSTITUTE(C14,""Sell_"",""""))))/2),ROUNDUP(INDEX(Upgrades!$C$3:$C$13,MATCH(C14,Upgrades!$B$3:$B$13,0))*1.15^(COUNTIF(C$4:C13,C14)-COUNTIF(C$4:C13,""Sell_""&C14))))))"),115.0) -> 115 | H14: =IF(COUNTA(C14:C1653)=0,"",G14+IF(H13<0,H13)) -> 115 | I14: =IF(COUNTA(C14:C1653)=0,"",I13+IF(H14>0,H14,0)/F13) -> 173.04307 | J14: =IF(COUNTA(C14:C1653)=0,"",IF(I14>3600,TRUNC(I14/3600)&"h ","")&IF(I14>59,IF(AND(I14>3599,QUOTIENT(MOD(I14,3600),60)<10),"0","")&QUOTIENT(MOD(I14,3600),60)&"m ","")&IF(AND(I14>=10,MOD(I14,60)<10),"0","")&ROUNDDOWN(MOD(I14,60),0)&"s") -> 2m 53s | K14: =IF(COUNTA(C14:C1653)=0,"",K13+IF(H14>0,H14,0)) -> 2789 | L14: =IFS(AND(COUNTA(C14:C1653)=0,COUNTA(Q14:Q1653)=0),"",OR(AND(K14>=1000000000,OR(Y14>=1000000000,COUNTA(Q14:Q1653)=0)),OR(Y14>=1000000000,AND(COUNTA(C14:C1653)=0,P$3=TRUE))),AF$1, AND(K14<1000000000,COUNTA(C14:C1653)>0,P$3=FALSE),TRUNC(LARGE(W$4:W1653,COUNTIF(Y$4:Y1653,">"&K14)+1)+(K14-LARGE(Y$4:Y1653,COUNTIF(Y$4:Y1653,">"&K14)+1))/LARGE(T$4:T1653,COUNTIF(Y$4:Y1653,">"&K14)+1)-I14,5),1, TRUNC(W14-LARGE(I$4:I1653,COUNTIF(K$4:K1653,">"&Y14)+1)-(Y14-LARGE(K$4:K1653,COUNTIF(K$4:K1653,">"&Y14)+1))/LARGE(F$4:F1653,COUNTIF(K$4:K1653,">"&Y14)+1),5)) -> 0 | M14: =IFERROR(__xludf.DUMMYFUNCTION("IFS(AND(COUNTA(C14:C1644)=0,COUNTA(Q14:Q1644)=0),"""",OR(AND(K14>=1000000000,OR(Y14>=1000000000,COUNTA(Q14:Q1644)=0)),OR(Y14>=1000000000,AND(COUNTA(C14:C1644)=0,P$3=TRUE))), ROUNDDOWN((AB$1-AC$1)*MAX(INDEX(T$4:T1644,MATCH(LARGE(FILTER(Y$4:Y1644,Y$4:Y1644<"&"1000000000),1),Y$4:Y1644)),INDEX(F$4:F1644,MATCH(LARGE(FILTER(K$4:K1644,K$4:K1644<1000000000),1),K$4:K1644)))),AND(K14<1000000000,COUNTA(C14:C1644)>0,P$3=FALSE), ROUNDDOWN(INDEX(Y$4:Y1644,MATCH(LARGE(FILTER(W$4:W1644,W$4:W1644<=I14),1),W$4:W1644))+(I14-LA"&"RGE(FILTER(W$4:W1644,W$4:W1644<=I14),1))*INDEX(T$4:T1644,MATCH(LARGE(FILTER(W$4:W1644,W$4:W1644<=I14),1),W$4:W1644))-K14),1, ROUNDDOWN(Y14-INDEX(K$4:K1644,MATCH(LARGE(FILTER(I$4:I1644,I$4:I1644<=W14),1),I$4:I1644))-(W14-LARGE(FILTER(I$4:I1644,I$4:I1644<=W"&"14),1))*INDEX(F$4:F1644,MATCH(LARGE(FILTER(I$4:I1644,I$4:I1644<=W14),1),I$4:I1644))))"),0.0) -> 0 | N14: =IF(ABS(L14)>=10000,TEXT(ROUND(L14,1),"#.#")&IF(RIGHT(TEXT(ROUND(L14,1),"#.#"))=",","0",""),L14) -> 0 | O14: =IF(ABS(M14)<1000000,M14,IF(ABS(M14)<1000000000,TEXT(ROUND(M14/1000000,1),"#.#")&IF(RIGHT(TEXT(ROUND(M14/1000000,1),"#.#"))=",","0","")&"M",TEXT(ROUND(M14/1000000000,1),"#.#")&IF(RIGHT(TEXT(ROUND(M14/1000000000,1),"#.#"))=",","0","")&"B")) -> 0 | P14: =IF(COUNTA(Q14:Q1653)=0,"",COUNTIF(Q$4:Q14,Q14)-COUNTIF(Q$4:Q14,"Sell_"&Q14)) -> 2 | Q14: Grandma | R14: =IFERROR(__xludf.DUMMYFUNCTION("IF(COUNTA(Q14:Q1644)=0,"""",IF(ISBLANK(Q14),FALSE,IF(NOT(COUNTIF($AA$24:$AA$34,SUBSTITUTE(Q14,""Sell_"",""""))),1,IF(REGEXMATCH(Q14,""Sell_""),IF(COUNTIF(Q$4:Q14,SUBSTITUTE(Q14,""Sell_"",""""))-COUNTIF(Q$4:Q13,Q14)<1,1),FALSE))))"),FALSE) -> FALSE | S14: {=IF(COUNTA(Q14:Q1644)=0,"",SUM((COUNTIF(Q$4:Q14,Upgrades!$B$3:$B$13)-COUNTIF(Q$4:Q14,"Sell_"&Upgrades!$B$3:$B$13))*Upgrades!$D$3:$D$13))} -> 17.4 | T14: =IFERROR(__xludf.DUMMYFUNCTION("IF(COUNTA(Q14:Q1644)=0,"""",IF(REGEXMATCH(INDEX(FILTER(Q$4:Q14,Q$4:Q14<>""""),ROWS(FILTER(Q$4:Q14,Q$4:Q14<>""""))),""^Sell_""),INDEX(FILTER(T$4:T13,Q$4:Q13<>""""),ROWS(FILTER(Q$4:Q13,Q$4:Q13<>""""))),$AD$5+S14))"),27.4) -> 27.4 | U14: =IFERROR(__xludf.DUMMYFUNCTION("IF(COUNTA(Q14:Q1644)=0,"""",IF(Q14="""",0,IF(REGEXMATCH(Q14,""^Sell_""),-ROUNDDOWN(ROUNDUP(INDEX(Upgrades!$C$3:$C$13,MATCH(SUBSTITUTE(Q14,""Sell_"",""""),Upgrades!$B$3:$B$13,0))*1.15^(COUNTIF(Q$4:Q13,SUBSTITUTE(Q14,""Sell_"",""""))-COUNTIF(Q$4:Q13,""Sell_"&"""&SUBSTITUTE(Q14,""Sell_"",""""))))/2),ROUNDUP(INDEX(Upgrades!$C$3:$C$13,MATCH(Q14,Upgrades!$B$3:$B$13,0))*1.15^(COUNTIF(Q$4:Q13,Q14)-COUNTIF(Q$4:Q13,""Sell_""&Q14))))))"),115.0) -> 115 | V14: =IF(COUNTA(Q14:Q1653)=0,"",U14+IF(V13<0,V13)) -> 115 | W14: =IF(COUNTA(Q14:Q1653)=0,"",W13+IF(V14>0,V14,0)/T13) -> 173.04307 | X14: =IF(COUNTA(Q14:Q1653)=0,"",IF(W14>3600,TRUNC(W14/3600)&"h ","")&IF(W14>59,IF(AND(W14>3599,QUOTIENT(MOD(W14,3600),60)<10),"0","")&QUOTIENT(MOD(W14,3600),60)&"m ","")&IF(AND(W14>=10,MOD(W14,60)<10),"0","")&ROUNDDOWN(MOD(W14,60),0)&"s") -> 2m 53s | Y14: =IF(COUNTA(Q14:Q1653)=0,"",Y13+IF(V14>0,V14,0)) -> 2789 | AA14: WARNING: Never cut things (Ctrl+X), always copy (Ctrl+C).
B15: =IF(COUNTA(C15:C1654)=0,"",COUNTIF(C$4:C15,C15)-COUNTIF(C$4:C15,"Sell_"&C15)) -> 5 | C15: Farm | D15: =IFERROR(__xludf.DUMMYFUNCTION("IF(COUNTA(C15:C1644)=0,"""",IF(ISBLANK(C15),FALSE,IF(NOT(COUNTIF($AA$24:$AA$34,SUBSTITUTE(C15,""Sell_"",""""))),1,IF(REGEXMATCH(C15,""Sell_""),IF(COUNTIF(C$4:C15,SUBSTITUTE(C15,""Sell_"",""""))-COUNTIF(C$4:C14,C15)<1,1),FALSE))))"),FALSE) -> FALSE | E15: {=IF(COUNTA(C15:C1644)=0,"",SUM((COUNTIF(C$4:C15,Upgrades!$B$3:$B$13)-COUNTIF(C$4:C15,"Sell_"&Upgrades!$B$3:$B$13))*Upgrades!$D$3:$D$13))} -> 21.4 | F15: =IFERROR(__xludf.DUMMYFUNCTION("IF(COUNTA(C15:C1644)=0,"""",IF(REGEXMATCH(INDEX(FILTER(C$4:C15,C$4:C15<>""""),ROWS(FILTER(C$4:C15,C$4:C15<>""""))),""^Sell_""),INDEX(FILTER(F$4:F14,C$4:C14<>""""),ROWS(FILTER(C$4:C14,C$4:C14<>""""))),$AC$5+E15))"),31.4) -> 31.4 | G15: =IFERROR(__xludf.DUMMYFUNCTION("IF(COUNTA(C15:C1644)=0,"""",IF(C15="""",0,IF(REGEXMATCH(C15,""^Sell_""),-ROUNDDOWN(ROUNDUP(INDEX(Upgrades!$C$3:$C$13,MATCH(SUBSTITUTE(C15,""Sell_"",""""),Upgrades!$B$3:$B$13,0))*1.15^(COUNTIF(C$4:C14,SUBSTITUTE(C15,""Sell_"",""""))-COUNTIF(C$4:C14,""Sell_"&"""&SUBSTITUTE(C15,""Sell_"",""""))))/2),ROUNDUP(INDEX(Upgrades!$C$3:$C$13,MATCH(C15,Upgrades!$B$3:$B$13,0))*1.15^(COUNTIF(C$4:C14,C15)-COUNTIF(C$4:C14,""Sell_""&C15))))))"),875.0) -> 875 | H15: =IF(COUNTA(C15:C1654)=0,"",G15+IF(H14<0,H14)) -> 875 | I15: =IF(COUNTA(C15:C1654)=0,"",I14+IF(H15>0,H15,0)/F14) -> 204.97737 | J15: =IF(COUNTA(C15:C1654)=0,"",IF(I15>3600,TRUNC(I15/3600)&"h ","")&IF(I15>59,IF(AND(I15>3599,QUOTIENT(MOD(I15,3600),60)<10),"0","")&QUOTIENT(MOD(I15,3600),60)&"m ","")&IF(AND(I15>=10,MOD(I15,60)<10),"0","")&ROUNDDOWN(MOD(I15,60),0)&"s") -> 3m 24s | K15: =IF(COUNTA(C15:C1654)=0,"",K14+IF(H15>0,H15,0)) -> 3664 | L15: =IFS(AND(COUNTA(C15:C1654)=0,COUNTA(Q15:Q1654)=0),"",OR(AND(K15>=1000000000,OR(Y15>=1000000000,COUNTA(Q15:Q1654)=0)),OR(Y15>=1000000000,AND(COUNTA(C15:C1654)=0,P$3=TRUE))),AF$1, AND(K15<1000000000,COUNTA(C15:C1654)>0,P$3=FALSE),TRUNC(LARGE(W$4:W1654,COUNTIF(Y$4:Y1654,">"&K15)+1)+(K15-LARGE(Y$4:Y1654,COUNTIF(Y$4:Y1654,">"&K15)+1))/LARGE(T$4:T1654,COUNTIF(Y$4:Y1654,">"&K15)+1)-I15,5),1, TRUNC(W15-LARGE(I$4:I1654,COUNTIF(K$4:K1654,">"&Y15)+1)-(Y15-LARGE(K$4:K1654,COUNTIF(K$4:K1654,">"&Y15)+1))/LARGE(F$4:F1654,COUNTIF(K$4:K1654,">"&Y15)+1),5)) -> 0 | M15: =IFERROR(__xludf.DUMMYFUNCTION("IFS(AND(COUNTA(C15:C1644)=0,COUNTA(Q15:Q1644)=0),"""",OR(AND(K15>=1000000000,OR(Y15>=1000000000,COUNTA(Q15:Q1644)=0)),OR(Y15>=1000000000,AND(COUNTA(C15:C1644)=0,P$3=TRUE))), ROUNDDOWN((AB$1-AC$1)*MAX(INDEX(T$4:T1644,MATCH(LARGE(FILTER(Y$4:Y1644,Y$4:Y1644<"&"1000000000),1),Y$4:Y1644)),INDEX(F$4:F1644,MATCH(LARGE(FILTER(K$4:K1644,K$4:K1644<1000000000),1),K$4:K1644)))),AND(K15<1000000000,COUNTA(C15:C1644)>0,P$3=FALSE), ROUNDDOWN(INDEX(Y$4:Y1644,MATCH(LARGE(FILTER(W$4:W1644,W$4:W1644<=I15),1),W$4:W1644))+(I15-LA"&"RGE(FILTER(W$4:W1644,W$4:W1644<=I15),1))*INDEX(T$4:T1644,MATCH(LARGE(FILTER(W$4:W1644,W$4:W1644<=I15),1),W$4:W1644))-K15),1, ROUNDDOWN(Y15-INDEX(K$4:K1644,MATCH(LARGE(FILTER(I$4:I1644,I$4:I1644<=W15),1),I$4:I1644))-(W15-LARGE(FILTER(I$4:I1644,I$4:I1644<=W"&"15),1))*INDEX(F$4:F1644,MATCH(LARGE(FILTER(I$4:I1644,I$4:I1644<=W15),1),I$4:I1644))))"),0.0) -> 0 | N15: =IF(ABS(L15)>=10000,TEXT(ROUND(L15,1),"#.#")&IF(RIGHT(TEXT(ROUND(L15,1),"#.#"))=",","0",""),L15) -> 0 | O15: =IF(ABS(M15)<1000000,M15,IF(ABS(M15)<1000000000,TEXT(ROUND(M15/1000000,1),"#.#")&IF(RIGHT(TEXT(ROUND(M15/1000000,1),"#.#"))=",","0","")&"M",TEXT(ROUND(M15/1000000000,1),"#.#")&IF(RIGHT(TEXT(ROUND(M15/1000000000,1),"#.#"))=",","0","")&"B")) -> 0 | P15: =IF(COUNTA(Q15:Q1654)=0,"",COUNTIF(Q$4:Q15,Q15)-COUNTIF(Q$4:Q15,"Sell_"&Q15)) -> 5 | Q15: Farm | R15: =IFERROR(__xludf.DUMMYFUNCTION("IF(COUNTA(Q15:Q1644)=0,"""",IF(ISBLANK(Q15),FALSE,IF(NOT(COUNTIF($AA$24:$AA$34,SUBSTITUTE(Q15,""Sell_"",""""))),1,IF(REGEXMATCH(Q15,""Sell_""),IF(COUNTIF(Q$4:Q15,SUBSTITUTE(Q15,""Sell_"",""""))-COUNTIF(Q$4:Q14,Q15)<1,1),FALSE))))"),FALSE) -> FALSE | S15: {=IF(COUNTA(Q15:Q1644)=0,"",SUM((COUNTIF(Q$4:Q15,Upgrades!$B$3:$B$13)-COUNTIF(Q$4:Q15,"Sell_"&Upgrades!$B$3:$B$13))*Upgrades!$D$3:$D$13))} -> 21.4 | T15: =IFERROR(__xludf.DUMMYFUNCTION("IF(COUNTA(Q15:Q1644)=0,"""",IF(REGEXMATCH(INDEX(FILTER(Q$4:Q15,Q$4:Q15<>""""),ROWS(FILTER(Q$4:Q15,Q$4:Q15<>""""))),""^Sell_""),INDEX(FILTER(T$4:T14,Q$4:Q14<>""""),ROWS(FILTER(Q$4:Q14,Q$4:Q14<>""""))),$AD$5+S15))"),31.4) -> 31.4 | U15: =IFERROR(__xludf.DUMMYFUNCTION("IF(COUNTA(Q15:Q1644)=0,"""",IF(Q15="""",0,IF(REGEXMATCH(Q15,""^Sell_""),-ROUNDDOWN(ROUNDUP(INDEX(Upgrades!$C$3:$C$13,MATCH(SUBSTITUTE(Q15,""Sell_"",""""),Upgrades!$B$3:$B$13,0))*1.15^(COUNTIF(Q$4:Q14,SUBSTITUTE(Q15,""Sell_"",""""))-COUNTIF(Q$4:Q14,""Sell_"&"""&SUBSTITUTE(Q15,""Sell_"",""""))))/2),ROUNDUP(INDEX(Upgrades!$C$3:$C$13,MATCH(Q15,Upgrades!$B$3:$B$13,0))*1.15^(COUNTIF(Q$4:Q14,Q15)-COUNTIF(Q$4:Q14,""Sell_""&Q15))))))"),875.0) -> 875 | V15: =IF(COUNTA(Q15:Q1654)=0,"",U15+IF(V14<0,V14)) -> 875 | W15: =IF(COUNTA(Q15:Q1654)=0,"",W14+IF(V15>0,V15,0)/T14) -> 204.97737 | X15: =IF(COUNTA(Q15:Q1654)=0,"",IF(W15>3600,TRUNC(W15/3600)&"h ","")&IF(W15>59,IF(AND(W15>3599,QUOTIENT(MOD(W15,3600),60)<10),"0","")&QUOTIENT(MOD(W15,3600),60)&"m ","")&IF(AND(W15>=10,MOD(W15,60)<10),"0","")&ROUNDDOWN(MOD(W15,60),0)&"s") -> 3m 24s | Y15: =IF(COUNTA(Q15:Q1654)=0,"",Y14+IF(V15>0,V15,0)) -> 3664 | AA15: Don't add or remove any row. If you need more rows, you
